Workbook

Sheet EmployeeLoan
A1: Employee Code | B1: Loan Amount | C1: LoanReleasedOn | D1: DeductFrom | E1: MonthlyAmount | F1: Status
A2: A1 | B2: 50000 | C2: march | D2: 44652 | E2: 8333
A3: A5 | B3: 20000 | C3: Sept | D3: 44835 | E3: 3333

Sheet SalaryMonth
B1: Month Start Date | C1: 26
B2: Salary Year | C2: 2022
A4: S.No | B4: Month | C4: Start Date | D4: End Date | E4: Work Days
A5: 1 | B5: 44652 | C5: 44646 | D5: 44676 | E5: =D5-C5+1 -> 31
A6: 2 | B6: 44682 | C6: 44677 | D6: 44706 | E6: =D6-C6+1 -> 30
A7: 3 | B7: 44713 | C7: 44707 | D7: 44737 | E7: =D7-C7+1 -> 31
A8: 4 | B8: 44743 | C8: 44738 | D8: 44767 | E8: =D8-C8+1 -> 30
A9: 5 | B9: 44774 | C9: 44768 | D9: 44798 | E9: =D9-C9+1 -> 31
A10: 6 | B10: 44805 | C10: 44799 | D10: 44829 | E10: =D10-C10+1 -> 31
A11: 7 | B11: 44835 | C11: 44830 | D11: 44859 | E11: =D11-C11+1 -> 30
A12: 8 | B12: 44866 | C12: 44860 | D12: 44890 | E12: =D12-C12+1 -> 31
A13: 9 | B13: 44896 | C13: 44891 | D13: 44920 | E13: =D13-C13+1 -> 30
A14: 10 | B14: 44927 | C14: 44921 | D14: 44951 | E14: =D14-C14+1 -> 31
A15: 11 | B15: 44958 | C15: 44952 | D15: 44982 | E15: =D15-C15+1 -> 31
A16: 12 | B16: 44986 | C16: 44983 | D16: 45010 | E16: =D16-C16+1 -> 28

Sheet Salary
A1: 1 | B1: =A1+1 -> 2 | C1: =B1+1 -> 3 | D1: =C1+1 -> 4 | E1: =D1+1 -> 5 | F1: =E1+1 -> 6 | G1: =F1+1 -> 7 | H1: =G1+1 -> 8 | I1: =H1+1 -> 9 | ... BB1: =BA1+1 -> 54
F2: Salary Actual | V2: Salary for pay | AB2: Salary Earned
A3: S.No | B3: Employee Code | C3: DOJ | D3: DOR | E3: Salary | F3: Basic | G3: HRA | H3: Medical & Transport Allowance | I3: Food Coupons | J3: Special Allowance | K3: Month | L3: Month Start | M3: Month End | N3: Month Days | O3: Is New Employee | P3: Is Left Employee | Q3: Employee Working days | R3: Days present | S3: LOP Days | T3: Late Coming days | U3: Unauthorized leaves | V3: Basic | W3: HRA | X3: Medical & Transport Allowance | Y3: Food Coupons | Z3: Special Allowance | AB3: Basic | AC3: HRA | AD3: Medical & Transport Allowance | AE3: Food Coupons | AF3: Special Allowance | AG3: Salary Earned (For ESI) | AH3: Arrears | AI3: Incentives | AJ3: Gross Earnings Total | AK3: LOP Amount | AL3: UA Amount | AM3: LC Amount | AN3: Staff Salary Advances | AO3: Food Coupons | AP3: Paycut | AQ3: Net Salary Earned | AR3: PT | AS3: Income Tax | AT3: PF Employee Contribution | AU3: ESI Employee Contribution | AV3: ESI Final | AW3: Gross Earnings | AX3: Gross Earnings For Tax | AY3: Gross Deduction | AZ3: Net Take Home | BA3: Comments | BB3: Income Tax Calculated This Month
A4: 1 | B4: A1 | C4: 40180 | E4: 62000 | F4: =E4*50% -> 31000 | G4: =F4*40% -> 12400 | H4: =IF(E4<11750,0,3500) -> 3500 | I4: 0 | J4: =E4-SUM(F4:I4) -> 15100 | K4: 44652 | L4: =VLOOKUP(K4,SalaryMonth!$B$5:$E$16,2,FALSE) -> 44646 | M4: =VLOOKUP(K4,SalaryMonth!$B$5:$E$16,3,FALSE) -> 44676 | N4: =VLOOKUP(K4,SalaryMonth!$B$5:$E$16,4,FALSE) -> 31 | O4: =IF(L4<=C4,"Y","N") -> N | P4: =IF(OR(D4<>"",M4<D4),"Y","N") -> N | Q4: 31 | R4: 28 | S4: 1 | T4: 1 | U4: 1 | V4: =ROUND((F4/N4)*Q4,0) -> 31000 | W4: =ROUND((G4/N4)*Q4,0) -> 12400 | X4: =ROUND((H4/N4)*Q4,0) -> 3500 | Y4: =(I4/N4)*Q4 -> 0 | Z4: =ROUND((J4/N4)*Q4,0) -> 15100 | AB4: =ROUND((V4/Q4)*Q4-(V4/Q4)*S4,0) -> 30000 | AC4: =ROUND((W4/Q4)*Q4-(W4/Q4)*S4,0) -> 12000 | AD4: =ROUND((X4/Q4)*Q4-(X4/Q4)*S4,0) -> 3387 | AE4: =Y4 -> 0 | AF4: =ROUND((Z4/Q4)*Q4-(Z4/Q4)*S4,0) -> 14613 | AG4: =SUM(AB4:AF4) -> 60000 | AH4: 1000 | AI4: 1000 | AJ4: =SUM(AB4:AI4) -> 122000 | AK4: =SUM(V4:Z4)-AG4 -> 2000 | AL4: =ROUND(E4*(U4/Q4),0) -> 2000 | AM4: =ROUND(E4*(T4/Q4),0) -> 2000 | AN4: 8333 | AO4: =AE4 -> 0 | AP4: 200 | AQ4: =SUM(F4:J4)-SUM(AK4:AP4) -> 47467 | AR4: =IF( AX4<15001,0,IF(AX4<20001,150,200)) -> 200 | AS4: 500 | AT4: =MIN( ROUND(AB4*12%,0),1800) -> 1800 | AU4: =ROUNDUP(IF(E4<=21000,AG4*1.75%,0),0) -> 0 | AV4: =AU4 -> 0 | AW4: =SUM(V4:Z4)+SUM(AH4:AI4) -> 64000 | AX4: =AW4-AP4-SUM(AK4:AM4) -> 57800 | AY4: =SUM(AK4:AP4)+SUM(AR4:AT4)+AV4 -> 17033 | AZ4: =AW4-AY4-BB4 -> 46967 | BA4: Arrears Incentives Added /Advance Deducted 8333/LATE Coming /UnAuthorized/incometax | BB4: 0
A5: =A4+1 -> 2 | B5: A2 | C5: 40180 | E5: 22000 | F5: =E5*50% -> 11000 | G5: =F5*40% -> 4400 | H5: =IF(E5<11750,0,3500) -> 3500 | I5: 0 | J5: =E5-SUM(F5:I5) -> 3100 | K5: 44652 | L5: =VLOOKUP(K5,SalaryMonth!$B$5:$E$16,2,FALSE) -> 44646 | M5: =VLOOKUP(K5,SalaryMonth!$B$5:$E$16,3,FALSE) -> 44676 | N5: =VLOOKUP(K5,SalaryMonth!$B$5:$E$16,4,FALSE) -> 31 | O5: =IF(L5<C5,"Y","N") -> N | P5: =IF(OR(D5<>"",M5<D5),"Y","N") -> N | Q5: 31 | R5: 29 | S5: 0 | T5: 0 | U5: 0 | V5: =ROUND((F5/N5)*Q5,0) -> 11000 | W5: =ROUND((G5/N5)*Q5,0) -> 4400 | X5: =ROUND((H5/N5)*Q5,0) -> 3500 | Y5: =(I5/N5)*Q5 -> 0 | Z5: =ROUND((J5/N5)*Q5,0) -> 3100 | AB5: =ROUND((V5/Q5)*Q5-(V5/Q5)*S5,0) -> 11000 | AC5: =ROUND((W5/Q5)*Q5-(W5/Q5)*S5,0) -> 4400 | AD5: =ROUND((X5/Q5)*Q5-(X5/Q5)*S5,0) -> 3500 | AE5: =I5 -> 0 | AF5: =ROUND((Z5/Q5)*Q5-(Z5/Q5)*S5,0) -> 3100 | AG5: =SUM(AB5:AF5) -> 22000 | AH5: 0 | AI5: 0 | AJ5: =SUM(AB5:AI5) -> 44000 | AK5: =SUM(V5:Z5)-AG5 -> 0 | AL5: =ROUND(E5*(U5/Q5),0) -> 0 | AM5: =ROUND(E5*(T5/Q5),0) -> 0 | AN5: 0 | AO5: =AE5 -> 0 | AP5: 0 | AQ5: =SUM(F5:J5)-SUM(AK5:AP5) -> 22000 | AR5: =IF( AX5<15001,0,IF(AX5<20001,150,200)) -> 200 | AS5: 0 | AT5: =MIN( ROUND(AB5*12%,0),1800) -> 1320 | AU5: =ROUNDUP(IF(E5<=21000,AG5*1.75%,0),0) -> 0 | AV5: =AU5 -> 0 | AW5: =SUM(V5:Z5)+SUM(AH5:AI5) -> 22000 | AX5: =AW5-AP5-SUM(AK5:AM5) -> 22000 | AY5: =SUM(AK5:AP5)+SUM(AR5:AT5)+AV5 -> 1520 | AZ5: =AW5-AY5-BB5 -> 20480 | BA5: ESI is not deducted because Employee salary is Not under ESI slab | BB5: 0
A6: =A5+1 -> 3 | B6: A3 | C6: 40181 | E6: 11000 | F6: =E6*50% -> 5500 | G6: =F6*40% -> 2200 | H6: =IF(E6<11750,0,3500) -> 0 | I6: 0 | J6: =E6-SUM(F6:I6) -> 3300 | K6: 44652 | L6: =VLOOKUP(K6,SalaryMonth!$B$5:$E$16,2,FALSE) -> 44646 | M6: =VLOOKUP(K6,SalaryMonth!$B$5:$E$16,3,FALSE) -> 44676 | N6: =VLOOKUP(K6,SalaryMonth!$B$5:$E$16,4,FALSE) -> 31 | O6: =IF(L6<C6,"Y","N") -> N | P6: =IF(OR(D6<>"",M6<D6),"Y","N") -> N | Q6: 31 | R6: 29 | S6: 0 | T6: 0 | U6: 0 | V6: =ROUND((F6/N6)*Q6,0) -> 5500 | W6: =ROUND((G6/N6)*Q6,0) -> 2200 | X6: =ROUND((H6/N6)*Q6,0) -> 0 | Y6: =(I6/N6)*Q6 -> 0 | Z6: =ROUND((J6/N6)*Q6,0) -> 3300 | AB6: =ROUND((V6/Q6)*Q6-(V6/Q6)*S6,0) -> 5500 | AC6: =ROUND((W6/Q6)*Q6-(W6/Q6)*S6,0) -> 2200 | AD6: =ROUND((X6/Q6)*Q6-(X6/Q6)*S6,0) -> 0 | AE6: =I6 -> 0 | AF6: =ROUND((Z6/Q6)*Q6-(Z6/Q6)*S6,0) -> 3300 | AG6: =SUM(AB6:AF6) -> 11000 | AH6: 0 | AI6: 0 | AJ6: =SUM(AB6:AI6) -> 22000 | AK6: =SUM(V6:Z6)-AG6 -> 0 | AL6: =ROUND(E6*(U6/Q6),0) -> 0 | AM6: =ROUND(E6*(T6/Q6),0) -> 0 | AN6: 0 | AO6: =AE6 -> 0 | AP6: 0 | AQ6: =SUM(F6:J6)-SUM(AK6:AP6) -> 11000 | AR6: =IF( AX6<15001,0,IF(AX6<20001,150,200)) -> 0 | AS6: 0 | AT6: =MIN( ROUND(AB6*12%,0),1800) -> 660 | AU6: =ROUNDUP(IF(E6<=21000,AG6*1.75%,0),0) -> 193 | AV6: =AU6 -> 193 | AW6: =SUM(V6:Z6)+SUM(AH6:AI6) -> 11000 | AX6: =AW6-AP6-SUM(AK6:AM6) -> 11000 | AY6: =SUM(AK6:AP6)+SUM(AR6:AT6)+AV6 -> 853 | AZ6: =AW6-AY6-BB6 -> 10147 | BA6: ESI is deducted because employee salary is under ESI slab
A7: =A6+1 -> 4 | B7: A4 | C7: 40182 | E7: 25000 | F7: =E7*50% -> 12500 | G7: =F7*40% -> 5000 | H7: =IF(E7<11750,0,3500) -> 3500 | I7: 0 | J7: =E7-SUM(F7:I7) -> 4000 | K7: 44652 | L7: =VLOOKUP(K7,SalaryMonth!$B$5:$E$16,2,FALSE) -> 44646 | M7: =VLOOKUP(K7,SalaryMonth!$B$5:$E$16,3,FALSE) -> 44676 | N7: =VLOOKUP(K7,SalaryMonth!$B$5:$E$16,4,FALSE) -> 31 | O7: =IF(L7<C7,"Y","N") -> N | P7: =IF(OR(D7<>"",M7<D7),"Y","N") -> N | Q7: 31 | R7: 29 | S7: 0 | T7: 0 | U7: 0 | V7: =ROUND((F7/N7)*Q7,0) -> 12500 | W7: =ROUND((G7/N7)*Q7,0) -> 5000 | X7: =ROUND((H7/N7)*Q7,0) -> 3500 | Y7: =(I7/N7)*Q7 -> 0 | Z7: =ROUND((J7/N7)*Q7,0) -> 4000 | AB7: =ROUND((V7/Q7)*Q7-(V7/Q7)*S7,0) -> 12500 | AC7: =ROUND((W7/Q7)*Q7-(W7/Q7)*S7,0) -> 5000 | AD7: =ROUND((X7/Q7)*Q7-(X7/Q7)*S7,0) -> 3500 | AE7: =I7 -> 0 | AF7: =ROUND((Z7/Q7)*Q7-(Z7/Q7)*S7,0) -> 4000 | AG7: =SUM(AB7:AF7) -> 25000 | AH7: 0 | AI7: 0 | AJ7: =SUM(AB7:AI7) -> 50000 | AK7: =SUM(V7:Z7)-AG7 -> 0 | AL7: =ROUND(E7*(U7/Q7),0) -> 0 | AM7: =ROUND(E7*(T7/Q7),0) -> 0 | AN7: 0 | AO7: =AE7 -> 0 | AP7: 0 | AQ7: =SUM(F7:J7)-SUM(AK7:AP7) -> 25000 | AR7: =IF( AX7<15001,0,IF(AX7<20001,150,200)) -> 200 | AS7: 0 | AT7: =MIN( ROUND(AB7*12%,0),1800) -> 1500 | AU7: =ROUNDUP(IF(E7<=21000,AG7*1.75%,0),0) -> 0 | AV7: =AU7 -> 0 | AW7: =SUM(V7:Z7)+SUM(AH7:AI7) -> 25000 | AX7: =AW7-AP7-SUM(AK7:AM7) -> 25000 | AY7: =SUM(AK7:AP7)+SUM(AR7:AT7)+AV7 -> 1700 | AZ7: =AW7-AY7-BB7 -> 23300
A8: =A7+1 -> 5 | B8: A5 | C8: 40183 | E8: 45000 | F8: =E8*50% -> 22500 | G8: =F8*40% -> 9000 | H8: =IF(E8<11750,0,3500) -> 3500 | I8: 2400 | J8: =E8-SUM(F8:I8) -> 7600 | K8: 44652 | L8: =VLOOKUP(K8,SalaryMonth!$B$5:$E$16,2,FALSE) -> 44646 | M8: =VLOOKUP(K8,SalaryMonth!$B$5:$E$16,3,FALSE) -> 44676 | N8: =VLOOKUP(K8,SalaryMonth!$B$5:$E$16,4,FALSE) -> 31 | O8: =IF(L8<C8,"Y","N") -> N | P8: =IF(OR(D8<>"",M8<D8),"Y","N") -> N | Q8: 31 | R8: 29 | S8: 0 | T8: 0 | U8: 0 | V8: =ROUND((F8/N8)*Q8,0) -> 22500 | W8: =ROUND((G8/N8)*Q8,0) -> 9000 | X8: =ROUND((H8/N8)*Q8,0) -> 3500 | Y8: =(I8/N8)*Q8 -> 2400 | Z8: =ROUND((J8/N8)*Q8,0) -> 7600 | AB8: =ROUND((V8/Q8)*Q8-(V8/Q8)*S8,0) -> 22500 | AC8: =ROUND((W8/Q8)*Q8-(W8/Q8)*S8,0) -> 9000 | AD8: =ROUND((X8/Q8)*Q8-(X8/Q8)*S8,0) -> 3500 | AE8: =I8 -> 2400 | AF8: =ROUND((Z8/Q8)*Q8-(Z8/Q8)*S8,0) -> 7600 | AG8: =SUM(AB8:AF8) -> 45000 | AH8: 0 | AI8: 0 | AJ8: =SUM(AB8:AI8) -> 90000 | AK8: =SUM(V8:Z8)-AG8 -> 0 | AL8: =ROUND(E8*(U8/Q8),0) -> 0 | AM8: =ROUND(E8*(T8/Q8),0) -> 0 | AN8: 0 | AO8: =AE8 -> 2400 | AP8: 0 | AQ8: =SUM(F8:J8)-SUM(AK8:AP8) -> 42600 | AR8: =IF( AX8<15001,0,IF(AX8<20001,150,200)) -> 200 | AS8: 2000 | AT8: =MIN( ROUND(AB8*12%,0),1800) -> 1800 | AU8: =ROUNDUP(IF(E8<=21000,AG8*1.75%,0),0) -> 0 | AV8: =AU8 -> 0 | AW8: =SUM(V8:Z8)+SUM(AH8:AI8) -> 45000 | AX8: =AW8-AP8-SUM(AK8:AM8) -> 45000 | AY8: =SUM(AK8:AP8)+SUM(AR8:AT8)+AV8 -> 6400 | AZ8: =AW8-AY8-BB8 -> 38600 | BA8: Income tax Added
A9: =A8+1 -> 6 | B9: B1 | C9: 40183 | E9: 120000 | F9: =E9*50% -> 60000 | G9: =F9*40% -> 24000 | H9: =IF(E9<11750,0,3500) -> 3500 | I9: 2400 | J9: =E9-SUM(F9:I9) -> 30100 | K9: 44652 | L9: =VLOOKUP(K9,SalaryMonth!$B$5:$E$16,2,FALSE) -> 44646 | M9: =VLOOKUP(K9,SalaryMonth!$B$5:$E$16,3,FALSE) -> 44676 | N9: =VLOOKUP(K9,SalaryMonth!$B$5:$E$16,4,FALSE) -> 31 | O9: =IF(L9<C9,"Y","N") -> N | P9: =IF(OR(D9<>"",M9<D9),"Y","N") -> N | Q9: 31 | R9: 31 | S9: 0 | T9: 0 | U9: 0 | V9: =ROUND((F9/N9)*Q9,0) -> 60000 | W9: =ROUND((G9/N9)*Q9,0) -> 24000 | X9: =ROUND((H9/N9)*Q9,0) -> 3500 | Y9: =(I9/N9)*Q9 -> 2400 | Z9: =ROUND((J9/N9)*Q9,0) -> 30100 | AB9: =ROUND((V9/Q9)*Q9-(V9/Q9)*S9,0) -> 60000 | AC9: =ROUND((W9/Q9)*Q9-(W9/Q9)*S9,0) -> 24000 | AD9: =ROUND((X9/Q9)*Q9-(X9/Q9)*S9,0) -> 3500 | AE9: =I9 -> 2400 | AF9: =ROUND((Z9/Q9)*Q9-(Z9/Q9)*S9,0) -> 30100 | AG9: =SUM(AB9:AF9) -> 120000 | AH9: 0 | AI9: 0 | AJ9: =SUM(AB9:AI9) -> 240000 | AK9: =SUM(V9:Z9)-AG9 -> 0 | AL9: =ROUND(E9*(U9/Q9),0) -> 0 | AM9: =ROUND(E9*(T9/Q9),0) -> 0 | AN9: 0 | AO9: =AE9 -> 2400 | AP9: 0 | AQ9: =SUM(F9:J9)-SUM(AK9:AP9) -> 117600 | AR9: =IF( AX9<15001,0,IF(AX9<20001,150,200)) -> 200 | AS9: 0 | AT9: =MIN( ROUND(AB9*12%,0),1800) -> 1800 | AU9: =ROUNDUP(IF(E9<=21000,AG9*1.75%,0),0) -> 0 | AV9: =AU9 -> 0 | AW9: =SUM(V9:Z9)+SUM(AH9:AI9) -> 120000 | AX9: =AW9-AP9-SUM(AK9:AM9) -> 120000 | AY9: =SUM(AK9:AP9)+SUM(AR9:AT9)+AV9 -> 4400 | AZ9: =AW9-AY9-BB9 -> 105280 | BA9: Income tax Added | BB9: 10320
A10: =A9+1 -> 7 | AK10: =SUM(V10:Z10)-AG10 -> 0 | AZ10: =AW10-AY10-BB10 -> 0
A11: =A10+1 -> 8 | B11: A1 | C11: 40180 | E11: 62000 | F11: =E11*50% -> 31000 | G11: =F11*40% -> 12400 | H11: =IF(E11<11750,0,3500) -> 3500 | I11: 0 | J11: =E11-SUM(F11:I11) -> 15100 | K11: 44682 | L11: =VLOOKUP(K11,SalaryMonth!$B$5:$E$16,2,FALSE) -> 44677 | M11: =VLOOKUP(K11,SalaryMonth!$B$5:$E$16,3,FALSE) -> 44706 | N11: =VLOOKUP(K11,SalaryMonth!$B$5:$E$16,4,FALSE) -> 30 | O11: =IF(L11<=C11,"Y","N") -> N | P11: =IF(OR(D11<>"",M11<D11),"Y","N") -> N | Q11: 30 | R11: 29 | S11: 1 | T11: 0 | U11: 0 | V11: =ROUND((F11/N11)*Q11,0) -> 31000 | W11: =ROUND((G11/N11)*Q11,0) -> 12400 | X11: =ROUND((H11/N11)*Q11,0) -> 3500 | Y11: =(I11/N11)*Q11 -> 0 | Z11: =ROUND((J11/N11)*Q11,0) -> 15100 | AB11: =ROUND((V11/Q11)*Q11-(V11/Q11)*S11,0) -> 29967 | AC11: =ROUND((W11/Q11)*Q11-(W11/Q11)*S11,0) -> 11987 | AD11: =ROUND((X11/Q11)*Q11-(X11/Q11)*S11,0) -> 3383 | AE11: =I11 -> 0 | AF11: =ROUND((Z11/Q11)*Q11-(Z11/Q11)*S11,0) -> 14597 | AG11: =SUM(AB11:AF11) -> 59934 | AH11: 0 | AI11: 1000 | AJ11: =SUM(AB11:AI11) -> 120868 | AK11: =SUM(V11:Z11)-AG11 -> 2066 | AL11: =ROUND(E11*(U11/Q11),0) -> 0 | AM11: =ROUND(E11*(T11/Q11),0) -> 0 | AN11: 8333 | AO11: =AE11 -> 0 | AP11: 0 | AQ11: =SUM(F11:J11)-SUM(AK11:AP11) -> 51601 | AR11: =IF( AX11<15001,0,IF(AX11<20001,150,200)) -> 200 | AS11: 0 | AT11: =MIN( ROUND(AB11*12%,0),1800) -> 1800 | AU11: =ROUNDUP(IF(E11<=21000,AG11*1.75%,0),0) -> 0 | AV11: =AU11 -> 0 | AW11: =SUM(V11:Z11)+SUM(AH11:AI11) -> 63000 | AX11: =AW11-AP11-SUM(AK11:AM11) -> 60934 | AY11: =SUM(AK11:AP11)+SUM(AR11:AT11)+AV11 -> 12399 | AZ11: =AW11-AY11-BB11 -> 47161 | BA11: incentives Added 1000rs/Advance Deducted 8333 | BB11: 3440
A12: =A11+1 -> 9 | B12: A2 | C12: 40180 | E12: 21000 | F12: =E12*50% -> 10500 | G12: =F12*40% -> 4200 | H12: =IF(E12<11750,0,3500) -> 3500 | I12: 0 | J12: =E12-SUM(F12:I12) -> 2800 | K12: 44682 | L12: =VLOOKUP(K12,SalaryMonth!$B$5:$E$16,2,FALSE) -> 44677 | M12: =VLOOKUP(K12,SalaryMonth!$B$5:$E$16,3,FALSE) -> 44706 | N12: =VLOOKUP(K12,SalaryMonth!$B$5:$E$16,4,FALSE) -> 30 | O12: =IF(L12<C12,"Y","N") -> N | P12: =IF(OR(D12<>"",M12<D12),"Y","N") -> N | Q12: 30 | R12: 29 | S12: 0 | T12: 0 | U12: 0 | V12: =ROUND((F12/N12)*Q12,0) -> 10500 | W12: =ROUND((G12/N12)*Q12,0) -> 4200 | X12: =ROUND((H12/N12)*Q12,0) -> 3500 | Y12: =(I12/N12)*Q12 -> 0 | Z12: =ROUND((J12/N12)*Q12,0) -> 2800 | AB12: =ROUND((V12/Q12)*Q12-(V12/Q12)*S12,0) -> 10500 | AC12: =ROUND((W12/Q12)*Q12-(W12/Q12)*S12,0) -> 4200 | AD12: =ROUND((X12/Q12)*Q12-(X12/Q12)*S12,0) -> 3500 | AE12: =Y12 -> 0 | AF12: =ROUND((Z12/Q12)*Q12-(Z12/Q12)*S12,0) -> 2800 | AG12: =SUM(AB12:AF12) -> 21000 | AH12: 0 | AI12: 0 | AJ12: =SUM(AB12:AI12) -> 42000 | AK12: =SUM(V12:Z12)-AG12 -> 0 | AL12: =ROUND(E12*(U12/Q12),0) -> 0 | AM12: =ROUND(E12*(T12/Q12),0) -> 0 | AN12: 0 | AO12: =AE12 -> 0 | AP12: 0 | AQ12: =SUM(F12:J12)-SUM(AK12:AP12) -> 21000 | AR12: =IF( AX12<15001,0,IF(AX12<20001,150,200)) -> 200 | AS12: 0 | AT12: =MIN( ROUND(AB12*12%,0),1800) -> 1260 | AU12: =ROUNDUP(IF(E12<=21000,AG12*1.75%,0),0) -> 368 | AV12: =AU12 -> 368 | AW12: =SUM(V12:Z12)+SUM(AH12:AI12) -> 21000 | AX12: =AW12-AP12-SUM(AK12:AM12) -> 21000 | AY12: =SUM(AK12:AP12)+SUM(AR12:AT12)+AV12 -> 1828 | AZ12: =AW12-AY12-BB12 -> 19172 | BA12: ESI is deducted because employee salary is under ESI slab
A13: =A12+1 -> 10 | B13: A3 | C13: 40181 | E13: 11000 | F13: =E13*50% -> 5500 | G13: =F13*40% -> 2200 | H13: =IF(E13<11750,0,3500) -> 0 | I13: 0 | J13: =E13-SUM(F13:I13) -> 3300 | K13: 44682 | L13: =VLOOKUP(K13,SalaryMonth!$B$5:$E$16,2,FALSE) -> 44677 | M13: =VLOOKUP(K13,SalaryMonth!$B$5:$E$16,3,FALSE) -> 44706 | N13: =VLOOKUP(K13,SalaryMonth!$B$5:$E$16,4,FALSE) -> 30 | O13: =IF(L13<C13,"Y","N") -> N | P13: =IF(OR(D13<>"",M13<D13),"Y","N") -> N | Q13: 30 | R13: 29 | S13: 0 | T13: 0 | U13: 0 | V13: =ROUND((F13/N13)*Q13,0) -> 5500 | W13: =ROUND((G13/N13)*Q13,0) -> 2200 | X13: =ROUND((H13/N13)*Q13,0) -> 0 | Y13: =(I13/N13)*Q13 -> 0 | Z13: =ROUND((J13/N13)*Q13,0) -> 3300 | AB13: =ROUND((V13/Q13)*Q13-(V13/Q13)*S13,0) -> 5500 | AC13: =ROUND((W13/Q13)*Q13-(W13/Q13)*S13,0) -> 2200 | AD13: =ROUND((X13/Q13)*Q13-(X13/Q13)*S13,0) -> 0 | AE13: =Y13 -> 0 | AF13: =ROUND((Z13/Q13)*Q13-(Z13/Q13)*S13,0) -> 3300 | AG13: =SUM(AB13:AF13) -> 11000 | AH13: 0 | AI13: 0 | AJ13: =SUM(AB13:AI13) -> 22000 | AK13: =SUM(V13:Z13)-AG13 -> 0 | AL13: =ROUND(E13*(U13/Q13),0) -> 0 | AM13: =ROUND(E13*(T13/Q13),0) -> 0 | AN13: 0 | AO13: =AE13 -> 0 | AP13: 0 | AQ13: =SUM(F13:J13)-SUM(AK13:AP13) -> 11000 | AR13: =IF( AX13<15001,0,IF(AX13<20001,150,200)) -> 0 | AS13: 0 | AT13: =MIN( ROUND(AB13*12%,0),1800) -> 660 | AU13: =ROUNDUP(IF(E13<=21000,AG13*1.75%,0),0) -> 193 | AV13: =AU13 -> 193 | AW13: =SUM(V13:Z13)+SUM(AH13:AI13) -> 11000 | AX13: =AW13-AP13-SUM(AK13:AM13) -> 11000 | AY13: =SUM(AK13:AP13)+SUM(AR13:AT13)+AV13 -> 853 | AZ13: =AW13-AY13-BB13 -> 10147 | BA13: ESI is deducted because employee salary is under ESI slab
A14: =A13+1 -> 11 | B14: A4 | C14: 40182 | E14: 25000 | F14: =E14*50% -> 12500 | G14: =F14*40% -> 5000 | H14: =IF(E14<11750,0,3500) -> 3500 | I14: 0 | J14: =E14-SUM(F14:I14) -> 4000 | K14: 44682 | L14: =VLOOKUP(K14,SalaryMonth!$B$5:$E$16,2,FALSE) -> 44677 | M14: =VLOOKUP(K14,SalaryMonth!$B$5:$E$16,3,FALSE) -> 44706 | N14: =VLOOKUP(K14,SalaryMonth!$B$5:$E$16,4,FALSE) -> 30 | O14: =IF(L14<C14,"Y","N") -> N | P14: =IF(OR(D14<>"",M14<D14),"Y","N") -> N | Q14: 30 | R14: 29 | S14: 0 | T14: 0 | U14: 0 | V14: =ROUND((F14/N14)*Q14,0) -> 12500 | W14: =ROUND((G14/N14)*Q14,0) -> 5000 | X14: =ROUND((H14/N14)*Q14,0) -> 3500 | Y14: =(I14/N14)*Q14 -> 0 | Z14: =ROUND((J14/N14)*Q14,0) -> 4000 | AB14: =ROUND((V14/Q14)*Q14-(V14/Q14)*S14,0) -> 12500 | AC14: =ROUND((W14/Q14)*Q14-(W14/Q14)*S14,0) -> 5000 | AD14: =ROUND((X14/Q14)*Q14-(X14/Q14)*S14,0) -> 3500 | AE14: =Y14 -> 0 | AF14: =ROUND((Z14/Q14)*Q14-(Z14/Q14)*S14,0) -> 4000 | AG14: =SUM(AB14:AF14) -> 25000 | AH14: 0 | AI14: 0 | AJ14: =SUM(AB14:AI14) -> 50000 | AK14: =SUM(V14:Z14)-AG14 -> 0 | AL14: =ROUND(E14*(U14/Q14),0) -> 0 | AM14: =ROUND(E14*(T14/Q14),0) -> 0 | AN14: 0 | AO14: =AE14 -> 0 | AP14: 0 | AQ14: =SUM(F14:J14)-SUM(AK14:AP14) -> 25000 | AR14: =IF( AX14<15001,0,IF(AX14<20001,150,200)) -> 200 | AS14: 0 | AT14: =MIN( ROUND(AB14*12%,0),1800) -> 1500 | AU14: =ROUNDUP(IF(E14<=21000,AG14*1.75%,0),0) -> 0 | AV14: =AU14 -> 0 | AW14: =SUM(V14:Z14)+SUM(AH14:AI14) -> 25000 | AX14: =AW14-AP14-SUM(AK14:AM14) -> 25000 | AY14: =SUM(AK14:AP14)+SUM(AR14:AT14)+AV14 -> 1700 | AZ14: =AW14-AY14-BB14 -> 23300
A15: =A14+1 -> 12 | B15: A5 | C15: 40183 | E15: 50000 | F15: =E15*50% -> 25000 | G15: =F15*40% -> 10000 | H15: =IF(E15<11750,0,3500) -> 3500 | I15: 2400 | J15: =E15-SUM(F15:I15) -> 9100 | K15: 44682 | L15: =VLOOKUP(K15,SalaryMonth!$B$5:$E$16,2,FALSE) -> 44677 | M15: =VLOOKUP(K15,SalaryMonth!$B$5:$E$16,3,FALSE) -> 44706 | N15: =VLOOKUP(K15,SalaryMonth!$B$5:$E$16,4,FALSE) -> 30 | O15: =IF(L15<C15,"Y","N") -> N | P15: =IF(OR(D15<>"",M15<D15),"Y","N") -> N | Q15: 30 | R15: 29 | S15: 0 | T15: 0 | U15: 0 | V15: =ROUND((F15/N15)*Q15,0) -> 25000 | W15: =ROUND((G15/N15)*Q15,0) -> 10000 | X15: =ROUND((H15/N15)*Q15,0) -> 3500 | Y15: =(I15/N15)*Q15 -> 2400 | Z15: =ROUND((J15/N15)*Q15,0) -> 9100 | AB15: =ROUND((V15/Q15)*Q15-(V15/Q15)*S15,0) -> 25000 | AC15: =ROUND((W15/Q15)*Q15-(W15/Q15)*S15,0) -> 10000 | AD15: =ROUND((X15/Q15)*Q15-(X15/Q15)*S15,0) -> 3500 | AE15: =Y15 -> 2400 | AF15: =ROUND((Z15/Q15)*Q15-(Z15/Q15)*S15,0) -> 9100 | AG15: =SUM(AB15:AF15) -> 50000 | AH15: 2000 | AI15: 0 | AJ15: =SUM(AB15:AI15) -> 102000 | AK15: =SUM(V15:Z15)-AG15 -> 0 | AL15: =ROUND(E15*(U15/Q15),0) -> 0 | AM15: =ROUND(E15*(T15/Q15),0) -> 0 | AN15: 0 | AO15: =AE15 -> 2400 | AP15: 0 | AQ15: =SUM(F15:J15)-SUM(AK15:AP15) -> 47600 | AR15: =IF( AX15<15001,0,IF(AX15<20001,150,200)) -> 200 | AS15: 2000 | AT15: =MIN( ROUND(AB15*12%,0),1800) -> 1800 | AU15: =ROUNDUP(IF(E15<=21000,AG15*1.75%,0),0) -> 0 | AV15: =AU15 -> 0 | AW15: =SUM(V15:Z15)+SUM(AH15:AI15) -> 52000 | AX15: =AW15-AP15-SUM(AK15:AM15) -> 52000 | AY15: =SUM(AK15:AP15)+SUM(AR15:AT15)+AV15 -> 6400 | AZ15: =AW15-AY15-BB15 -> 45600 | BA15: Income tax Added/Arrears Added
A16: =A15+1 -> 13 | B16: B1 | C16: 40183 | E16: 120000 | F16: =E16*50% -> 60000 | G16: =F16*40% -> 24000 | H16: =IF(E16<11750,0,3500) -> 3500 | I16: 2400 | J16: =E16-SUM(F16:I16) -> 30100 | K16: 44682 | L16: =VLOOKUP(K16,SalaryMonth!$B$5:$E$16,2,FALSE) -> 44677 | M16: =VLOOKUP(K16,SalaryMonth!$B$5:$E$16,3,FALSE) -> 44706 | N16: =VLOOKUP(K16,SalaryMonth!$B$5:$E$16,4,FALSE) -> 30 | O16: =IF(L16<C16,"Y","N") -> N | P16: =IF(OR(D16<>"",M16<D16),"Y","N") -> N | Q16: 30 | R16: 30 | S16: 0 | T16: 0 | U16: 0 | V16: =ROUND((F16/N16)*Q16,0) -> 60000 | W16: =ROUND((G16/N16)*Q16,0) -> 24000 | X16: =ROUND((H16/N16)*Q16,0) -> 3500 | Y16: =(I16/N16)*Q16 -> 2400 | Z16: =ROUND((J16/N16)*Q16,0) -> 30100 | AB16: =ROUND((V16/Q16)*Q16-(V16/Q16)*S16,0) -> 60000 | AC16: =ROUND((W16/Q16)*Q16-(W16/Q16)*S16,0) -> 24000 | AD16: =ROUND((X16/Q16)*Q16-(X16/Q16)*S16,0) -> 3500 | AE16: =I16 -> 2400 | AF16: =ROUND((Z16/Q16)*Q16-(Z16/Q16)*S16,0) -> 30100 | AG16: =SUM(AB16:AF16) -> 120000 | AH16: 0 | AI16: 0 | AJ16: =SUM(AB16:AI16) -> 240000 | AK16: =SUM(V16:Z16)-AG16 -> 0 | AL16: =ROUND(E16*(U16/Q16),0) -> 0 | AM16: =ROUND(E16*(T16/Q16),0) -> 0 | AN16: 0 | AO16: =AE16 -> 2400 | AP16: 0 | AQ16: =SUM(F16:J16)-SUM(AK16:AP16) -> 117600 | AR16: =IF( AX16<15001,0,IF(AX16<20001,150,200)) -> 200 | AS16: 0 | AT16: =MIN( ROUND(AB16*12%,0),1800) -> 1800 | AU16: =ROUNDUP(IF(E16<=21000,AG16*1.75%,0),0) -> 0 | AV16: =AU16 -> 0 | AW16: =SUM(V16:Z16)+SUM(AH16:AI16) -> 120000 | AX16: =AW16-AP16-SUM(AK16:AM16) -> 120000 | AY16: =SUM(AK16:AP16)+SUM(AR16:AT16)+AV16 -> 4400 | AZ16: =AW16-AY16-BB16 -> 105280 | BA16: Income tax Added | BB16: 10320
A17: =A16+1 -> 14 | AK17: =SUM(V17:Z17)-AG17 -> 0 | AZ17: =AW17-AY17-BB17 -> 0
A18: =A17+1 -> 15 | B18: A1 | C18: 40180 | E18: 62000 | F18: =E18*50% -> 31000 | G18: =F18*40% -> 12400 | H18: =IF(E18<11750,0,3500) -> 3500 | I18: 0 | J18: =E18-SUM(F18:I18) -> 15100 | K18: 44713 | L18: =VLOOKUP(K18,SalaryMonth!$B$5:$E$16,2,FALSE) -> 44707 | M18: =VLOOKUP(K18,SalaryMonth!$B$5:$E$16,3,FALSE) -> 44737 | N18: =VLOOKUP(K18,SalaryMonth!$B$5:$E$16,4,FALSE) -> 31 | O18: =IF(L18<=C18,"Y","N") -> N | P18: =IF(OR(D18<>"",M18<D18),"Y","N") -> N | Q18: 31 | R18: 29 | S18: 1 | T18: 0 | U18: 0 | V18: =ROUND((F18/N18)*Q18,0) -> 31000 | W18: =ROUND((G18/N18)*Q18,0) -> 12400 | X18: =ROUND((H18/N18)*Q18,0) -> 3500 | Y18: =(I18/N18)*Q18 -> 0 | Z18: =ROUND((J18/N18)*Q18,0) -> 15100 | AB18: =ROUND((V18/Q18)*Q18-(V18/Q18)*S18,0) -> 30000 | AC18: =ROUND((W18/Q18)*Q18-(W18/Q18)*S18,0) -> 12000 | AD18: =ROUND((X18/Q18)*Q18-(X18/Q18)*S18,0) -> 3387 | AE18: =Y18 -> 0 | AF18: =ROUND((Z18/Q18)*Q18-(Z18/Q18)*S18,0) -> 14613 | AG18: =SUM(AB18:AF18) -> 60000 | AH18: 0 | AI18: 0 | AJ18: =SUM(AB18:AI18) -> 120000 | AK18: =SUM(V18:Z18)-AG18 -> 2000 | AL18: =ROUND(E18*(U18/Q18),0) -> 0 | AM18: =ROUND(E18*(T18/Q18),0) -> 0 | AN18: 8333 | AO18: =AE18 -> 0 | AP18: 0 | AQ18: =SUM(F18:J18)-SUM(AK18:AP18) -> 51667 | AR18: =IF( AX18<15001,0,IF(AX18<20001,150,200)) -> 200 | AS18: 0 | AT18: =MIN( ROUND(AB18*12%,0),1800) -> 1800 | AU18: =ROUNDUP(IF(E18<=21000,AG18*1.75%,0),0) -> 0 | AV18: =AU18 -> 0 | AW18: =SUM(V18:Z18)+SUM(AH18:AI18) -> 62000 | AX18: =AW18-AP18-SUM(AK18:AM18) -> 60000 | AY18: =SUM(AK18:AP18)+SUM(AR18:AT18)+AV18 -> 12333 | AZ18: =AW18-AY18-BB18 -> 46297 | BA18: /Advance Deducted 8333 | BB18: 3370
A19: =A18+1 -> 16 | B19: A2 | C19: 40180 | E19: 24000 | F19: =E19*50% -> 12000 | G19: =F19*40% -> 4800 | H19: =IF(E19<11750,0,3500) -> 3500 | I19: 0 | J19: =E19-SUM(F19:I19) -> 3700 | K19: 44713 | L19: =VLOOKUP(K19,SalaryMonth!$B$5:$E$16,2,FALSE) -> 44707 | M19: =VLOOKUP(K19,SalaryMonth!$B$5:$E$16,3,FALSE) -> 44737 | N19: =VLOOKUP(K19,SalaryMonth!$B$5:$E$16,4,FALSE) -> 31 | O19: =IF(L19<C19,"Y","N") -> N | P19: =IF(OR(D19<>"",M19<D19),"Y","N") -> N | Q19: 31 | R19: 29 | S19: 0 | T19: 0 | U19: 0 | V19: =ROUND((F19/N19)*Q19,0) -> 12000 | W19: =ROUND((G19/N19)*Q19,0) -> 4800 | X19: =ROUND((H19/N19)*Q19,0) -> 3500 | Y19: =(I19/N19)*Q19 -> 0 | Z19: =ROUND((J19/N19)*Q19,0) -> 3700 | AB19: =ROUND((V19/Q19)*Q19-(V19/Q19)*S19,0) -> 12000 | AC19: =ROUND((W19/Q19)*Q19-(W19/Q19)*S19,0) -> 4800 | AD19: =ROUND((X19/Q19)*Q19-(X19/Q19)*S19,0) -> 3500 | AE19: =Y19 -> 0 | AF19: =ROUND((Z19/Q19)*Q19-(Z19/Q19)*S19,0) -> 3700 | AG19: =SUM(AB19:AF19) -> 24000 | AH19: 0 | AI19: 0 | AJ19: =SUM(AB19:AI19) -> 48000 | AK19: =SUM(V19:Z19)-AG19 -> 0 | AL19: =ROUND(E19*(U19/Q19),0) -> 0 | AM19: =ROUND(E19*(T19/Q19),0) -> 0 | AN19: 0 | AO19: =AE19 -> 0 | AP19: 0 | AQ19: =SUM(F19:J19)-SUM(AK19:AP19) -> 24000 | AR19: =IF( AX19<15001,0,IF(AX19<20001,150,200)) -> 200 | AS19: 0 | AT19: =MIN( ROUND(AB19*12%,0),1800) -> 1440 | AU19: =ROUNDUP(IF(E19<=21000,AG19*1.75%,0),0) -> 0 | AV19: =ROUNDUP(AG19 *1.75%,0) -> 420 | AW19: =SUM(V19:Z19)+SUM(AH19:AI19) -> 24000 | AX19: =AW19-AP19-SUM(AK19:AM19) -> 24000 | AY19: =SUM(AK19:AP19)+SUM(AR19:AT19)+AV19 -> 2060 | AZ19: =AW19-AY19-BB19 -> 21940 | BA19: ESI should be deducted because ESI is deducted in May month it will continue up to sep irrespective of salary
A20: =A19+1 -> 17 | B20: A3 | C20: 40181 | E20: 11000 | F20: =E20*50% -> 5500 | G20: =F20*40% -> 2200 | H20: =IF(E20<11750,0,3500) -> 0 | I20: 0 | J20: =E20-SUM(F20:I20) -> 3300 | K20: 44713 | L20: =VLOOKUP(K20,SalaryMonth!$B$5:$E$16,2,FALSE) -> 44707 | M20: =VLOOKUP(K20,SalaryMonth!$B$5:$E$16,3,FALSE) -> 44737 | N20: =VLOOKUP(K20,SalaryMonth!$B$5:$E$16,4,FALSE) -> 31 | O20: =IF(L20<C20,"Y","N") -> N | P20: =IF(OR(D20<>"",M20<D20),"Y","N") -> N | Q20: 31 | R20: 29 | S20: 0 | T20: 0 | U20: 0 | V20: =ROUND((F20/N20)*Q20,0) -> 5500 | W20: =ROUND((G20/N20)*Q20,0) -> 2200 | X20: =ROUND((H20/N20)*Q20,0) -> 0 | Y20: =(I20/N20)*Q20 -> 0 | Z20: =ROUND((J20/N20)*Q20,0) -> 3300 | AB20: =ROUND((V20/Q20)*Q20-(V20/Q20)*S20,0) -> 5500 | AC20: =ROUND((W20/Q20)*Q20-(W20/Q20)*S20,0) -> 2200 | AD20: =ROUND((X20/Q20)*Q20-(X20/Q20)*S20,0) -> 0 | AE20: =Y20 -> 0 | AF20: =ROUND((Z20/Q20)*Q20-(Z20/Q20)*S20,0) -> 3300 | AG20: =SUM(AB20:AF20) -> 11000 | AH20: 0 | AI20: 0 | AJ20: =SUM(AB20:AI20) -> 22000 | AK20: =SUM(V20:Z20)-AG20 -> 0 | AL20: =ROUND(E20*(U20/Q20),0) -> 0 | AM20: =ROUND(E20*(T20/Q20),0) -> 0 | AN20: 0 | AO20: =AE20 -> 0 | AP20: 0 | AQ20: =SUM(F20:J20)-SUM(AK20:AP20) -> 11000 | AR20: =IF( AX20<15001,0,IF(AX20<20001,150,200)) -> 0 | AS20: 0 | AT20: =MIN( ROUND(AB20*12%,0),1800) -> 660 | AU20: =ROUNDUP(IF(E20<=21000,AG20*1.75%,0),0) -> 193 | AV20: =AU20 -> 193 | AW20: =SUM(V20:Z20)+SUM(AH20:AI20) -> 11000 | AX20: =AW20-AP20-SUM(AK20:AM20) -> 11000 | AY20: =SUM(AK20:AP20)+SUM(AR20:AT20)+AV20 -> 853 | AZ20: =AW20-AY20-BB20 -> 10147 | BA20: ESI is deducted because employee salary is under ESI slab
A21: =A20+1 -> 18 | B21: A4 | C21: 40182 | E21: 25000 | F21: =E21*50% -> 12500 | G21: =F21*40% -> 5000 | H21: =IF(E21<11750,0,3500) -> 3500 | I21: 0 | J21: =E21-SUM(F21:I21) -> 4000 | K21: 44713 | L21: =VLOOKUP(K21,SalaryMonth!$B$5:$E$16,2,FALSE) -> 44707 | M21: =VLOOKUP(K21,SalaryMonth!$B$5:$E$16,3,FALSE) -> 44737 | N21: =VLOOKUP(K21,SalaryMonth!$B$5:$E$16,4,FALSE) -> 31 | O21: =IF(L21<C21,"Y","N") -> N | P21: =IF(OR(D21<>"",M21<D21),"Y","N") -> N | Q21: 31 | R21: 29 | S21: 0 | T21: 0 | U21: 0 | V21: =ROUND((F21/N21)*Q21,0) -> 12500 | W21: =ROUND((G21/N21)*Q21,0) -> 5000 | X21: =ROUND((H21/N21)*Q21,0) -> 3500 | Y21: =(I21/N21)*Q21 -> 0 | Z21: =ROUND((J21/N21)*Q21,0) -> 4000 | AB21: =ROUND((V21/Q21)*Q21-(V21/Q21)*S21,0) -> 12500 | AC21: =ROUND((W21/Q21)*Q21-(W21/Q21)*S21,0) -> 5000 | AD21: =ROUND((X21/Q21)*Q21-(X21/Q21)*S21,0) -> 3500 | AE21: =Y21 -> 0 | AF21: =ROUND((Z21/Q21)*Q21-(Z21/Q21)*S21,0) -> 4000 | AG21: =SUM(AB21:AF21) -> 25000 | AH21: 0 | AI21: 0 | AJ21: =SUM(AB21:AI21) -> 50000 | AK21: =SUM(V21:Z21)-AG21 -> 0 | AL21: =ROUND(E21*(U21/Q21),0) -> 0 | AM21: =ROUND(E21*(T21/Q21),0) -> 0 | AN21: 0 | AO21: =AE21 -> 0 | AP21: 0 | AQ21: =SUM(F21:J21)-SUM(AK21:AP21) -> 25000 | AR21: =IF( AX21<15001,0,IF(AX21<20001,150,200)) -> 200 | AS21: 0 | AT21: =MIN( ROUND(AB21*12%,0),1800) -> 1500 | AU21: =ROUNDUP(IF(E21<=21000,AG21*1.75%,0),0) -> 0 | AV21: =AU21 -> 0 | AW21: =SUM(V21:Z21)+SUM(AH21:AI21) -> 25000 | AX21: =AW21-AP21-SUM(AK21:AM21) -> 25000 | AY21: =SUM(AK21:AP21)+SUM(AR21:AT21)+AV21 -> 1700 | AZ21: =AW21-AY21-BB21 -> 23300
A22: =A21+1 -> 19 | B22: A5 | C22: 40183 | E22: 32000 | F22: =E22*50% -> 16000 | G22: =F22*40% -> 6400 | H22: =IF(E22<11750,0,3500) -> 3500 | I22: 0 | J22: =E22-SUM(F22:I22) -> 6100 | K22: 44713 | L22: =VLOOKUP(K22,SalaryMonth!$B$5:$E$16,2,FALSE) -> 44707 | M22: =VLOOKUP(K22,SalaryMonth!$B$5:$E$16,3,FALSE) -> 44737 | N22: =VLOOKUP(K22,SalaryMonth!$B$5:$E$16,4,FALSE) -> 31 | O22: =IF(L22<C22,"Y","N") -> N | P22: =IF(OR(D22<>"",M22<D22),"Y","N") -> N | Q22: 31 | R22: 29 | S22: 0 | T22: 0 | U22: 0 | V22: =ROUND((F22/N22)*Q22,0) -> 16000 | W22: =ROUND((G22/N22)*Q22,0) -> 6400 | X22: =ROUND((H22/N22)*Q22,0) -> 3500 | Y22: =(I22/N22)*Q22 -> 0 | Z22: =ROUND((J22/N22)*Q22,0) -> 6100 | AB22: =ROUND((V22/Q22)*Q22-(V22/Q22)*S22,0) -> 16000 | AC22: =ROUND((W22/Q22)*Q22-(W22/Q22)*S22,0) -> 6400 | AD22: =ROUND((X22/Q22)*Q22-(X22/Q22)*S22,0) -> 3500 | AE22: =Y22 -> 0 | AF22: =ROUND((Z22/Q22)*Q22-(Z22/Q22)*S22,0) -> 6100 | AG22: =SUM(AB22:AF22) -> 32000 | AH22: 0 | AI22: 0 | AJ22: =SUM(AB22:AI22) -> 64000 | AK22: =SUM(V22:Z22)-AG22 -> 0 | AL22: =ROUND(E22*(U22/Q22),0) -> 0 | AM22: =ROUND(E22*(T22/Q22),0) -> 0 | AN22: 0 | AO22: =AE22 -> 0 | AP22: 0 | AQ22: =SUM(F22:J22)-SUM(AK22:AP22) -> 32000 | AR22: =IF( AX22<15001,0,IF(AX22<20001,150,200)) -> 200 | AS22: 0 | AT22: =MIN( ROUND(AB22*12%,0),1800) -> 1800 | AU22: =ROUNDUP(IF(E22<=21000,AG22*1.75%,0),0) -> 0 | AV22: =AU22 -> 0 | AW22: =SUM(V22:Z22)+SUM(AH22:AI22) -> 32000 | AX22: =AW22-AP22-SUM(AK22:AM22) -> 32000 | AY22: =SUM(AK22:AP22)+SUM(AR22:AT22)+AV22 -> 2000 | AZ22: =AW22-AY22-BB22 -> 30000
A23: =A22+1 -> 20 | B23: B1 | C23: 40183 | E23: 120000 | F23: =E23*50% -> 60000 | G23: =F23*40% -> 24000 | H23: =IF(E23<11750,0,3500) -> 3500 | I23: 2400 | J23: =E23-SUM(F23:I23) -> 30100 | K23: 44713 | L23: =VLOOKUP(K23,SalaryMonth!$B$5:$E$16,2,FALSE) -> 44707 | M23: =VLOOKUP(K23,SalaryMonth!$B$5:$E$16,3,FALSE) -> 44737 | N23: =VLOOKUP(K23,SalaryMonth!$B$5:$E$16,4,FALSE) -> 31 | O23: =IF(L23<C23,"Y","N") -> N | P23: =IF(OR(D23<>"",M23<D23),"Y","N") -> N | Q23: 31 | R23: 31 | S23: 0 | T23: 0 | U23: 0 | V23: =ROUND((F23/N23)*Q23,0) -> 60000 | W23: =ROUND((G23/N23)*Q23,0) -> 24000 | X23: =ROUND((H23/N23)*Q23,0) -> 3500 | Y23: =(I23/N23)*Q23 -> 2400 | Z23: =ROUND((J23/N23)*Q23,0) -> 30100 | AB23: =ROUND((V23/Q23)*Q23-(V23/Q23)*S23,0) -> 60000 | AC23: =ROUND((W23/Q23)*Q23-(W23/Q23)*S23,0) -> 24000 | AD23: =ROUND((X23/Q23)*Q23-(X23/Q23)*S23,0) -> 3500 | AE23: =I23 -> 2400 | AF23: =ROUND((Z23/Q23)*Q23-(Z23/Q23)*S23,0) -> 30100 | AG23: =SUM(AB23:AF23) -> 120000 | AH23: 0 | AI23: 0 | AJ23: =SUM(AB23:AI23) -> 240000 | AK23: =SUM(V23:Z23)-AG23 -> 0 | AL23: =ROUND(E23*(U23/Q23),0) -> 0 | AM23: =ROUND(E23*(T23/Q23),0) -> 0 | AN23: 0 | AO23: =AE23 -> 2400 | AP23: 0 | AQ23: =SUM(F23:J23)-SUM(AK23:AP23) -> 117600 | AR23: =IF( AX23<15001,0,IF(AX23<20001,150,200)) -> 200 | AS23: 0 | AT23: =MIN( ROUND(AB23*12%,0),1800) -> 1800 | AU23: =ROUNDUP(IF(E23<=21000,AG23*1.75%,0),0) -> 0 | AV23: =AU23 -> 0 | AW23: =SUM(V23:Z23)+SUM(AH23:AI23) -> 120000 | AX23: =AW23-AP23-SUM(AK23:AM23) -> 120000 | AY23: =SUM(AK23:AP23)+SUM(AR23:AT23)+AV23 -> 4400 | AZ23: =AW23-AY23-BB23 -> 105280 | BA23: Income tax Added | BB23: 10320
A24: =A23+1 -> 21 | AK24: =SUM(V24:Z24)-AG24 -> 0 | AZ24: =AW24-AY24-BB24 -> 0
A25: =A24+1 -> 22 | B25: A1 | C25: 40180 | E25: 62000 | F25: =E25*50% -> 31000 | G25: =F25*40% -> 12400 | H25: =IF(E25<11750,0,3500) -> 3500 | I25: 0 | J25: =E25-SUM(F25:I25) -> 15100 | K25: 44743 | L25: =VLOOKUP(K25,SalaryMonth!$B$5:$E$16,2,FALSE) -> 44738 | M25: =VLOOKUP(K25,SalaryMonth!$B$5:$E$16,3,FALSE) -> 44767 | N25: =VLOOKUP(K25,SalaryMonth!$B$5:$E$16,4,FALSE) -> 30 | O25: =IF(L25<=C25,"Y","N") -> N | P25: =IF(OR(D25<>"",M25<D25),"Y","N") -> N | Q25: 30 | R25: 29 | S25: 1 | T25: 0 | U25: 0 | V25: =ROUND((F25/N25)*Q25,0) -> 31000 | W25: =ROUND((G25/N25)*Q25,0) -> 12400 | X25: =ROUND((H25/N25)*Q25,0) -> 3500 | Y25: =(I25/N25)*Q25 -> 0 | Z25: =ROUND((J25/N25)*Q25,0) -> 15100 | AB25: =ROUND((V25/Q25)*Q25-(V25/Q25)*S25,0) -> 29967 | AC25: =ROUND((W25/Q25)*Q25-(W25/Q25)*S25,0) -> 11987 | AD25: =ROUND((X25/Q25)*Q25-(X25/Q25)*S25,0) -> 3383 | AE25: =Y25 -> 0 | AF25: =ROUND((Z25/Q25)*Q25-(Z25/Q25)*S25,0) -> 14597 | AG25: =SUM(AB25:AF25) -> 59934 | AH25: 0 | AI25: 0 | AJ25: =SUM(AB25:AI25) -> 119868 | AK25: =SUM(V25:Z25)-AG25 -> 2066 | AL25: =ROUND(E25*(U25/Q25),0) -> 0 | AM25: =ROUND(E25*(T25/Q25),0) -> 0 | AN25: 8333 | AO25: =AE25 -> 0 | AP25: 0 | AQ25: =SUM(F25:J25)-SUM(AK25:AP25) -> 51601 | AR25: =IF( AX25<15001,0,IF(AX25<20001,150,200)) -> 200 | AS25: 2000 | AT25: =MIN( ROUND(AB25*12%,0),1800) -> 1800 | AU25: =ROUNDUP(IF(E25<=21000,AG25*1.75%,0),0) -> 0 | AV25: =AU25 -> 0 | AW25: =SUM(V25:Z25)+SUM(AH25:AI25) -> 62000 | AX25: =AW25-AP25-SUM(AK25:AM25) -> 59934 | AY25: =SUM(AK25:AP25)+SUM(AR25:AT25)+AV25 -> 14399 | AZ25: =AW25-AY25-BB25 -> 47601 | BA25: Advance Deducted 8333/income Tax
A26: =A25+1 -> 23 | B26: A2 | C26: 40180 | E26: 25000 | F26: =E26*50% -> 12500 | G26: =F26*40% -> 5000 | H26: =IF(E26<11750,0,3500) -> 3500 | I26: 0 | J26: =E26-SUM(F26:I26) -> 4000 | K26: 44743 | L26: =VLOOKUP(K26,SalaryMonth!$B$5:$E$16,2,FALSE) -> 44738 | M26: =VLOOKUP(K26,SalaryMonth!$B$5:$E$16,3,FALSE) -> 44767 | N26: =VLOOKUP(K26,SalaryMonth!$B$5:$E$16,4,FALSE) -> 30 | O26: =IF(L26<C26,"Y","N") -> N | P26: =IF(OR(D26<>"",M26<D26),"Y","N") -> N | Q26: 30 | R26: 29 | S26: 0 | T26: 0 | U26: 0 | V26: =ROUND((F26/N26)*Q26,0) -> 12500 | W26: =ROUND((G26/N26)*Q26,0) -> 5000 | X26: =ROUND((H26/N26)*Q26,0) -> 3500 | Y26: =(I26/N26)*Q26 -> 0 | Z26: =ROUND((J26/N26)*Q26,0) -> 4000 | AB26: =ROUND((V26/Q26)*Q26-(V26/Q26)*S26,0) -> 12500 | AC26: =ROUND((W26/Q26)*Q26-(W26/Q26)*S26,0) -> 5000 | AD26: =ROUND((X26/Q26)*Q26-(X26/Q26)*S26,0) -> 3500 | AE26: =Y26 -> 0 | AF26: =ROUND((Z26/Q26)*Q26-(Z26/Q26)*S26,0) -> 4000 | AG26: =SUM(AB26:AF26) -> 25000 | AH26: 0 | AI26: 0 | AJ26: =SUM(AB26:AI26) -> 50000 | AK26: =SUM(V26:Z26)-AG26 -> 0 | AL26: =ROUND(E26*(U26/Q26),0) -> 0 | AM26: =ROUND(E26*(T26/Q26),0) -> 0 | AN26: 0 | AO26: =AE26 -> 0 | AP26: 0 | AQ26: =SUM(F26:J26)-SUM(AK26:AP26) -> 25000 | AR26: =IF( AX26<15001,0,IF(AX26<20001,150,200)) -> 200 | AS26: 0 | AT26: =MIN( ROUND(AB26*12%,0),1800) -> 1500 | AU26: =ROUNDUP(IF(E26<=21000,AG26*1.75%,0),0) -> 0 | AV26: =ROUNDUP(AG26 *1.75%,0) -> 438 | AW26: =SUM(V26:Z26)+SUM(AH26:AI26) -> 25000 | AX26: =AW26-AP26-SUM(AK26:AM26) -> 25000 | AY26: =SUM(AK26:AP26)+SUM(AR26:AT26)+AV26 -> 2138 | AZ26: =AW26-AY26-BB26 -> 22862 | BA26: ESI should be deducted because ESI is deducted in May month it will continue up to sep irrespective of salary
A27: =A26+1 -> 24 | B27: A3 | C27: 40181 | E27: 11000 | F27: =E27*50% -> 5500 | G27: =F27*40% -> 2200 | H27: =IF(E27<11750,0,3500) -> 0 | I27: 0 | J27: =E27-SUM(F27:I27) -> 3300 | K27: 44743 | L27: =VLOOKUP(K27,SalaryMonth!$B$5:$E$16,2,FALSE) -> 44738 | M27: =VLOOKUP(K27,SalaryMonth!$B$5:$E$16,3,FALSE) -> 44767 | N27: =VLOOKUP(K27,SalaryMonth!$B$5:$E$16,4,FALSE) -> 30 | O27: =IF(L27<C27,"Y","N") -> N | P27: =IF(OR(D27<>"",M27<D27),"Y","N") -> N | Q27: 30 | R27: 29 | S27: 0 | T27: 0 | U27: 0 | V27: =ROUND((F27/N27)*Q27,0) -> 5500 | W27: =ROUND((G27/N27)*Q27,0) -> 2200 | X27: =ROUND((H27/N27)*Q27,0) -> 0 | Y27: =(I27/N27)*Q27 -> 0 | Z27: =ROUND((J27/N27)*Q27,0) -> 3300 | AB27: =ROUND((V27/Q27)*Q27-(V27/Q27)*S27,0) -> 5500 | AC27: =ROUND((W27/Q27)*Q27-(W27/Q27)*S27,0) -> 2200 | AD27: =ROUND((X27/Q27)*Q27-(X27/Q27)*S27,0) -> 0 | AE27: =Y27 -> 0 | AF27: =ROUND((Z27/Q27)*Q27-(Z27/Q27)*S27,0) -> 3300 | AG27: =SUM(AB27:AF27) -> 11000 | AH27: 0 | AI27: 0 | AJ27: =SUM(AB27:AI27) -> 22000 | AK27: =SUM(V27:Z27)-AG27 -> 0 | AL27: =ROUND(E27*(U27/Q27),0) -> 0 | AM27: =ROUND(E27*(T27/Q27),0) -> 0 | AN27: 0 | AO27: =AE27 -> 0 | AP27: 0 | AQ27: =SUM(F27:J27)-SUM(AK27:AP27) -> 11000 | AR27: =IF( AX27<15001,0,IF(AX27<20001,150,200)) -> 0 | AS27: 0 | AT27: =MIN( ROUND(AB27*12%,0),1800) -> 660 | AU27: =ROUNDUP(IF(E27<=21000,AG27*1.75%,0),0) -> 193 | AV27: =AU27 -> 193 | AW27: =SUM(V27:Z27)+SUM(AH27:AI27) -> 11000 | AX27: =AW27-AP27-SUM(AK27:AM27) -> 11000 | AY27: =SUM(AK27:AP27)+SUM(AR27:AT27)+AV27 -> 853 | AZ27: =AW27-AY27-BB27 -> 10147 | BA27: ESI is deducted because employee salary is under ESI slab
A28: =A27+1 -> 25 | B28: A4 | C28: 40182 | E28: 25000 | F28: =E28*50% -> 12500 | G28: =F28*40% -> 5000 | H28: =IF(E28<11750,0,3500) -> 3500 | I28: 0 | J28: =E28-SUM(F28:I28) -> 4000 | K28: 44743 | L28: =VLOOKUP(K28,SalaryMonth!$B$5:$E$16,2,FALSE) -> 44738 | M28: =VLOOKUP(K28,SalaryMonth!$B$5:$E$16,3,FALSE) -> 44767 | N28: =VLOOKUP(K28,SalaryMonth!$B$5:$E$16,4,FALSE) -> 30 | O28: =IF(L28<C28,"Y","N") -> N | P28: =IF(OR(D28<>"",M28<D28),"Y","N") -> N | Q28: 30 | R28: 29 | S28: 0 | T28: 0 | U28: 0 | V28: =ROUND((F28/N28)*Q28,0) -> 12500 | W28: =ROUND((G28/N28)*Q28,0) -> 5000 | X28: =ROUND((H28/N28)*Q28,0) -> 3500 | Y28: =(I28/N28)*Q28 -> 0 | Z28: =ROUND((J28/N28)*Q28,0) -> 4000 | AB28: =ROUND((V28/Q28)*Q28-(V28/Q28)*S28,0) -> 12500 | AC28: =ROUND((W28/Q28)*Q28-(W28/Q28)*S28,0) -> 5000 | AD28: =ROUND((X28/Q28)*Q28-(X28/Q28)*S28,0) -> 3500 | AE28: =Y28 -> 0 | AF28: =ROUND((Z28/Q28)*Q28-(Z28/Q28)*S28,0) -> 4000 | AG28: =SUM(AB28:AF28) -> 25000 | AH28: 0 | AI28: 0 | AJ28: =SUM(AB28:AI28) -> 50000 | AK28: =SUM(V28:Z28)-AG28 -> 0 | AL28: =ROUND(E28*(U28/Q28),0) -> 0 | AM28: =ROUND(E28*(T28/Q28),0) -> 0 | AN28: 0 | AO28: =AE28 -> 0 | AP28: 2000 | AQ28: =SUM(F28:J28)-SUM(AK28:AP28) -> 23000 | AR28: =IF( AX28<15001,0,IF(AX28<20001,150,200)) -> 200 | AS28: 0 | AT28: =MIN( ROUND(AB28*12%,0),1800) -> 1500 | AU28: =ROUNDUP(IF(E28<=21000,AG28*1.75%,0),0) -> 0 | AV28: =AU28 -> 0 | AW28: =SUM(V28:Z28)+SUM(AH28:AI28) -> 25000 | AX28: =AW28-AP28-SUM(AK28:AM28) -> 23000 | AY28: =SUM(AK28:AP28)+SUM(AR28:AT28)+AV28 -> 3700 | AZ28: =AW28-AY28-BB28 -> 21300 | BA28: Paycut added 2000
A29: =A28+1 -> 26 | B29: A5 | C29: 40183 | E29: 32000 | F29: =E29*50% -> 16000 | G29: =F29*40% -> 6400 | H29: =IF(E29<11750,0,3500) -> 3500 | I29: 0 | J29: =E29-SUM(F29:I29) -> 6100 | K29: 44743 | L29: =VLOOKUP(K29,SalaryMonth!$B$5:$E$16,2,FALSE) -> 44738 | M29: =VLOOKUP(K29,SalaryMonth!$B$5:$E$16,3,FALSE) -> 44767 | N29: =VLOOKUP(K29,SalaryMonth!$B$5:$E$16,4,FALSE) -> 30 | O29: =IF(L29<C29,"Y","N") -> N | P29: =IF(OR(D29<>"",M29<D29),"Y","N") -> N | Q29: 30 | R29: 29 | S29: 0 | T29: 0 | U29: 0 | V29: =ROUND((F29/N29)*Q29,0) -> 16000 | W29: =ROUND((G29/N29)*Q29,0) -> 6400 | X29: =ROUND((H29/N29)*Q29,0) -> 3500 | Y29: =(I29/N29)*Q29 -> 0 | Z29: =ROUND((J29/N29)*Q29,0) -> 6100 | AB29: =ROUND((V29/Q29)*Q29-(V29/Q29)*S29,0) -> 16000 | AC29: =ROUND((W29/Q29)*Q29-(W29/Q29)*S29,0) -> 6400 | AD29: =ROUND((X29/Q29)*Q29-(X29/Q29)*S29,0) -> 3500 | AE29: =Y29 -> 0 | AF29: =ROUND((Z29/Q29)*Q29-(Z29/Q29)*S29,0) -> 6100 | AG29: =SUM(AB29:AF29) -> 32000 | AH29: 0 | AI29: 0 | AJ29: =SUM(AB29:AI29) -> 64000 | AK29: =SUM(V29:Z29)-AG29 -> 0 | AL29: =ROUND(E29*(U29/Q29),0) -> 0 | AM29: =ROUND(E29*(T29/Q29),0) -> 0 | AN29: 0 | AO29: =AE29 -> 0 | AP29: 0 | AQ29: =SUM(F29:J29)-SUM(AK29:AP29) -> 32000 | AR29: =IF( AX29<15001,0,IF(AX29<20001,150,200)) -> 200 | AS29: 0 | AT29: =MIN( ROUND(AB29*12%,0),1800) -> 1800 | AU29: =ROUNDUP(IF(E29<=21000,AG29*1.75%,0),0) -> 0 | AV29: =AU29 -> 0 | AW29: =SUM(V29:Z29)+SUM(AH29:AI29) -> 32000 | AX29: =AW29-AP29-SUM(AK29:AM29) -> 32000 | AY29: =SUM(AK29:AP29)+SUM(AR29:AT29)+AV29 -> 2000 | AZ29: =AW29-AY29-BB29 -> 30000
A30: =A29+1 -> 27 | B30: B1 | C30: 40183 | E30: 120000 | F30: =E30*50% -> 60000 | G30: =F30*40% -> 24000 | H30: =IF(E30<11750,0,3500) -> 3500 | I30: 2400 | J30: =E30-SUM(F30:I30) -> 30100 | K30: 44743 | L30: =VLOOKUP(K30,SalaryMonth!$B$5:$E$16,2,FALSE) -> 44738 | M30: =VLOOKUP(K30,SalaryMonth!$B$5:$E$16,3,FALSE) -> 44767 | N30: =VLOOKUP(K30,SalaryMonth!$B$5:$E$16,4,FALSE) -> 30 | O30: =IF(L30<C30,"Y","N") -> N | P30: =IF(OR(D30<>"",M30<D30),"Y","N") -> N | Q30: 30 | R30: 30 | S30: 0 | T30: 0 | U30: 0 | V30: =ROUND((F30/N30)*Q30,0) -> 60000 | W30: =ROUND((G30/N30)*Q30,0) -> 24000 | X30: =ROUND((H30/N30)*Q30,0) -> 3500 | Y30: =(I30/N30)*Q30 -> 2400 | Z30: =ROUND((J30/N30)*Q30,0) -> 30100 | AB30: =ROUND((V30/Q30)*Q30-(V30/Q30)*S30,0) -> 60000 | AC30: =ROUND((W30/Q30)*Q30-(W30/Q30)*S30,0) -> 24000 | AD30: =ROUND((X30/Q30)*Q30-(X30/Q30)*S30,0) -> 3500 | AE30: =I30 -> 2400 | AF30: =ROUND((Z30/Q30)*Q30-(Z30/Q30)*S30,0) -> 30100 | AG30: =SUM(AB30:AF30) -> 120000 | AH30: 0 | AI30: 0 | AJ30: =SUM(AB30:AI30) -> 240000 | AK30: =SUM(V30:Z30)-AG30 -> 0 | AL30: =ROUND(E30*(U30/Q30),0) -> 0 | AM30: =ROUND(E30*(T30/Q30),0) -> 0 | AN30: 0 | AO30: =AE30 -> 2400 | AP30: 0 | AQ30: =SUM(F30:J30)-SUM(AK30:AP30) -> 117600 | AR30: =IF( AX30<15001,0,IF(AX30<20001,150,200)) -> 200 | AS30: 0 | AT30: =MIN( ROUND(AB30*12%,0),1800) -> 1800 | AU30: =ROUNDUP(IF(E30<=21000,AG30*1.75%,0),0) -> 0 | AV30: =AU30 -> 0 | AW30: =SUM(V30:Z30)+SUM(AH30:AI30) -> 120000 | AX30: =AW30-AP30-SUM(AK30:AM30) -> 120000 | AY30: =SUM(AK30:AP30)+SUM(AR30:AT30)+AV30 -> 4400 | AZ30: =AW30-AY30-BB30 -> 105280 | BA30: Income tax Added | BB30: 10320
A31: =A30+1 -> 28 | AK31: =SUM(V31:Z31)-AG31 -> 0 | AZ31: =AW31-AY31-BB31 -> 0
A32: =A31+1 -> 29 | B32: A1 | C32: 40180 | E32: 62000 | F32: =E32*50% -> 31000 | G32: =F32*40% -> 12400 | H32: =IF(E32<11750,0,3500) -> 3500 | I32: 0 | J32: =E32-SUM(F32:I32) -> 15100 | K32: 44774 | L32: =VLOOKUP(K32,SalaryMonth!$B$5:$E$16,2,FALSE) -> 44768 | M32: =VLOOKUP(K32,SalaryMonth!$B$5:$E$16,3,FALSE) -> 44798 | N32: =VLOOKUP(K32,SalaryMonth!$B$5:$E$16,4,FALSE) -> 31 | O32: =IF(L32<=C32,"Y","N") -> N | P32: =IF(OR(D32<>"",M32<D32),"Y","N") -> N | Q32: 31 | R32: 29 | S32: 1 | T32: 0 | U32: 0 | V32: =ROUND((F32/N32)*Q32,0) -> 31000 | W32: =ROUND((G32/N32)*Q32,0) -> 12400 | X32: =ROUND((H32/N32)*Q32,0) -> 3500 | Y32: =(I32/N32)*Q32 -> 0 | Z32: =ROUND((J32/N32)*Q32,0) -> 15100 | AB32: =ROUND((V32/Q32)*Q32-(V32/Q32)*S32,0) -> 30000 | AC32: =ROUND((W32/Q32)*Q32-(W32/Q32)*S32,0) -> 12000 | AD32: =ROUND((X32/Q32)*Q32-(X32/Q32)*S32,0) -> 3387 | AE32: =Y32 -> 0 | AF32: =ROUND((Z32/Q32)*Q32-(Z32/Q32)*S32,0) -> 14613 | AG32: =SUM(AB32:AF32) -> 60000 | AH32: 0 | AI32: 0 | AJ32: =SUM(AB32:AI32) -> 120000 | AK32: =SUM(V32:Z32)-AG32 -> 2000 | AL32: =ROUND(E32*(U32/Q32),0) -> 0 | AM32: =ROUND(E32*(T32/Q32),0) -> 0 | AN32: 8333 | AO32: =AE32 -> 0 | AP32: 0 | AQ32: =SUM(F32:J32)-SUM(AK32:AP32) -> 51667 | AR32: =IF( AX32<15001,0,IF(AX32<20001,150,200)) -> 200 | AS32: 200 | AT32: =MIN( ROUND(AB32*12%,0),1800) -> 1800 | AU32: =ROUNDUP(IF(E32<=21000,AG32*1.75%,0),0) -> 0 | AV32: =AU32 -> 0 | AW32: =SUM(V32:Z32)+SUM(AH32:AI32) -> 62000 | AX32: =AW32-AP32-SUM(AK32:AM32) -> 60000 | AY32: =SUM(AK32:AP32)+SUM(AR32:AT32)+AV32 -> 12533 | AZ32: =AW32-AY32-BB32 -> 49467 | BA32: Advance Deducted 8333/income tax
A33: =A32+1 -> 30 | B33: A2 | C33: 40180 | E33: 17000 | F33: =E33*50% -> 8500 | G33: =F33*40% -> 3400 | H33: =IF(E33<11750,0,3500) -> 3500 | I33: 0 | J33: =E33-SUM(F33:I33) -> 1600 | K33: 44774 | L33: =VLOOKUP(K33,SalaryMonth!$B$5:$E$16,2,FALSE) -> 44768 | M33: =VLOOKUP(K33,SalaryMonth!$B$5:$E$16,3,FALSE) -> 44798 | N33: =VLOOKUP(K33,SalaryMonth!$B$5:$E$16,4,FALSE) -> 31 | O33: =IF(L33<C33,"Y","N") -> N | P33: =IF(OR(D33<>"",M33<D33),"Y","N") -> N | Q33: 31 | R33: 29 | S33: 0 | T33: 0 | U33: 0 | V33: =ROUND((F33/N33)*Q33,0) -> 8500 | W33: =ROUND((G33/N33)*Q33,0) -> 3400 | X33: =ROUND((H33/N33)*Q33,0) -> 3500 | Y33: =(I33/N33)*Q33 -> 0 | Z33: =ROUND((J33/N33)*Q33,0) -> 1600 | AB33: =ROUND((V33/Q33)*Q33-(V33/Q33)*S33,0) -> 8500 | AC33: =ROUND((W33/Q33)*Q33-(W33/Q33)*S33,0) -> 3400 | AD33: =ROUND((X33/Q33)*Q33-(X33/Q33)*S33,0) -> 3500 | AE33: =Y33 -> 0 | AF33: =ROUND((Z33/Q33)*Q33-(Z33/Q33)*S33,0) -> 1600 | AG33: =SUM(AB33:AF33) -> 17000 | AH33: 0 | AI33: 0 | AJ33: =SUM(AB33:AI33) -> 34000 | AK33: =SUM(V33:Z33)-AG33 -> 0 | AL33: =ROUND(E33*(U33/Q33),0) -> 0 | AM33: =ROUND(E33*(T33/Q33),0) -> 0 | AN33: 0 | AO33: =AE33 -> 0 | AP33: 0 | AQ33: =SUM(F33:J33)-SUM(AK33:AP33) -> 17000 | AR33: =IF( AX33<15001,0,IF(AX33<20001,150,200)) -> 150 | AS33: 0 | AT33: =MIN( ROUND(AB33*12%,0),1800) -> 1020 | AU33: =ROUNDUP(IF(E33<=21000,AG33*1.75%,0),0) -> 298 | AV33: =AU33 -> 298 | AW33: =SUM(V33:Z33)+SUM(AH33:AI33) -> 17000 | AX33: =AW33-AP33-SUM(AK33:AM33) -> 17000 | AY33: =SUM(AK33:AP33)+SUM(AR33:AT33)+AV33 -> 1468 | AZ33: =AW33-AY33-BB33 -> 15532 | BA33: ESI should be deducted because ESI is deducted in May month it will continue up to sep irrespective of salary
A34: =A33+1 -> 31 | B34: A3 | C34: 40181 | E34: 11000 | F34: =E34*50% -> 5500 | G34: =F34*40% -> 2200 | H34: =IF(E34<11750,0,3500) -> 0 | I34: 0 | J34: =E34-SUM(F34:I34) -> 3300 | K34: 44774 | L34: =VLOOKUP(K34,SalaryMonth!$B$5:$E$16,2,FALSE) -> 44768 | M34: =VLOOKUP(K34,SalaryMonth!$B$5:$E$16,3,FALSE) -> 44798 | N34: =VLOOKUP(K34,SalaryMonth!$B$5:$E$16,4,FALSE) -> 31 | O34: =IF(L34<C34,"Y","N") -> N | P34: =IF(OR(D34<>"",M34<D34),"Y","N") -> N | Q34: 31 | R34: 29 | S34: 0 | T34: 0 | U34: 0 | V34: =ROUND((F34/N34)*Q34,0) -> 5500 | W34: =ROUND((G34/N34)*Q34,0) -> 2200 | X34: =ROUND((H34/N34)*Q34,0) -> 0 | Y34: =(I34/N34)*Q34 -> 0 | Z34: =ROUND((J34/N34)*Q34,0) -> 3300 | AB34: =ROUND((V34/Q34)*Q34-(V34/Q34)*S34,0) -> 5500 | AC34: =ROUND((W34/Q34)*Q34-(W34/Q34)*S34,0) -> 2200 | AD34: =ROUND((X34/Q34)*Q34-(X34/Q34)*S34,0) -> 0 | AE34: =Y34 -> 0 | AF34: =ROUND((Z34/Q34)*Q34-(Z34/Q34)*S34,0) -> 3300 | AG34: =SUM(AB34:AF34) -> 11000 | AH34: 0 | AI34: 0 | AJ34: =SUM(AB34:AI34) -> 22000 | AK34: =SUM(V34:Z34)-AG34 -> 0 | AL34: =ROUND(E34*(U34/Q34),0) -> 0 | AM34: =ROUND(E34*(T34/Q34),0) -> 0 | AN34: 0 | AO34: =AE34 -> 0 | AP34: 0 | AQ34: =SUM(F34:J34)-SUM(AK34:AP34) -> 11000 | AR34: =IF( AX34<15001,0,IF(AX34<20001,150,200)) -> 0 | AS34: 0 | AT34: =MIN( ROUND(AB34*12%,0),1800) -> 660 | AU34: =ROUNDUP(IF(E34<=21000,AG34*1.75%,0),0) -> 193 | AV34: =AU34 -> 193 | AW34: =SUM(V34:Z34)+SUM(AH34:AI34) -> 11000 | AX34: =AW34-AP34-SUM(AK34:AM34) -> 11000 | AY34: =SUM(AK34:AP34)+SUM(AR34:AT34)+AV34 -> 853 | AZ34: =AW34-AY34-BB34 -> 10147 | BA34: ESI is deducted because employee salary is under ESI slab
A35: =A34+1 -> 32 | B35: A4 | C35: 40182 | E35: 25000 | F35: =E35*50% -> 12500 | G35: =F35*40% -> 5000 | H35: =IF(E35<11750,0,3500) -> 3500 | I35: 0 | J35: =E35-SUM(F35:I35) -> 4000 | K35: 44774 | L35: =VLOOKUP(K35,SalaryMonth!$B$5:$E$16,2,FALSE) -> 44768 | M35: =VLOOKUP(K35,SalaryMonth!$B$5:$E$16,3,FALSE) -> 44798 | N35: =VLOOKUP(K35,SalaryMonth!$B$5:$E$16,4,FALSE) -> 31 | O35: =IF(L35<C35,"Y","N") -> N | P35: =IF(OR(D35<>"",M35<D35),"Y","N") -> N | Q35: 31 | R35: 29 | S35: 0 | T35: 0 | U35: 0 | V35: =ROUND((F35/N35)*Q35,0) -> 12500 | W35: =ROUND((G35/N35)*Q35,0) -> 5000 | X35: =ROUND((H35/N35)*Q35,0) -> 3500 | Y35: =(I35/N35)*Q35 -> 0 | Z35: =ROUND((J35/N35)*Q35,0) -> 4000 | AB35: =ROUND((V35/Q35)*Q35-(V35/Q35)*S35,0) -> 12500 | AC35: =ROUND((W35/Q35)*Q35-(W35/Q35)*S35,0) -> 5000 | AD35: =ROUND((X35/Q35)*Q35-(X35/Q35)*S35,0) -> 3500 | AE35: =Y35 -> 0 | AF35: =ROUND((Z35/Q35)*Q35-(Z35/Q35)*S35,0) -> 4000 | AG35: =SUM(AB35:AF35) -> 25000 | AH35: 0 | AI35: 0 | AJ35: =SUM(AB35:AI35) -> 50000 | AK35: =SUM(V35:Z35)-AG35 -> 0 | AL35: =ROUND(E35*(U35/Q35),0) -> 0 | AM35: =ROUND(E35*(T35/Q35),0) -> 0 | AN35: 0 | AO35: =AE35 -> 0 | AP35: 2000 | AQ35: =SUM(F35:J35)-SUM(AK35:AP35) -> 23000 | AR35: =IF( AX35<15001,0,IF(AX35<20001,150,200)) -> 200 | AS35: 0 | AT35: =MIN( ROUND(AB35*12%,0),1800) -> 1500 | AU35: =ROUNDUP(IF(E35<=21000,AG35*1.75%,0),0) -> 0 | AV35: =AU35 -> 0 | AW35: =SUM(V35:Z35)+SUM(AH35:AI35) -> 25000 | AX35: =AW35-AP35-SUM(AK35:AM35) -> 23000 | AY35: =SUM(AK35:AP35)+SUM(AR35:AT35)+AV35 -> 3700 | AZ35: =AW35-AY35-BB35 -> 21300 | BA35: paycut added 2000
A36: =A35+1 -> 33 | B36: A5 | C36: 40183 | E36: 32000 | F36: =E36*50% -> 16000 | G36: =F36*40% -> 6400 | H36: =IF(E36<11750,0,3500) -> 3500 | I36: 0 | J36: =E36-SUM(F36:I36) -> 6100 | K36: 44774 | L36: =VLOOKUP(K36,SalaryMonth!$B$5:$E$16,2,FALSE) -> 44768 | M36: =VLOOKUP(K36,SalaryMonth!$B$5:$E$16,3,FALSE) -> 44798 | N36: =VLOOKUP(K36,SalaryMonth!$B$5:$E$16,4,FALSE) -> 31 | O36: =IF(L36<C36,"Y","N") -> N | P36: =IF(OR(D36<>"",M36<D36),"Y","N") -> N | Q36: 31 | R36: 29 | S36: 0 | T36: 0 | U36: 0 | V36: =ROUND((F36/N36)*Q36,0) -> 16000 | W36: =ROUND((G36/N36)*Q36,0) -> 6400 | X36: =ROUND((H36/N36)*Q36,0) -> 3500 | Y36: =(I36/N36)*Q36 -> 0 | Z36: =ROUND((J36/N36)*Q36,0) -> 6100 | AB36: =ROUND((V36/Q36)*Q36-(V36/Q36)*S36,0) -> 16000 | AC36: =ROUND((W36/Q36)*Q36-(W36/Q36)*S36,0) -> 6400 | AD36: =ROUND((X36/Q36)*Q36-(X36/Q36)*S36,0) -> 3500 | AE36: =Y36 -> 0 | AF36: =ROUND((Z36/Q36)*Q36-(Z36/Q36)*S36,0) -> 6100 | AG36: =SUM(AB36:AF36) -> 32000 | AH36: 0 | AI36: 0 | AJ36: =SUM(AB36:AI36) -> 64000 | AK36: =SUM(V36:Z36)-AG36 -> 0 | AL36: =ROUND(E36*(U36/Q36),0) -> 0 | AM36: =ROUND(E36*(T36/Q36),0) -> 0 | AN36: 0 | AO36: =AE36 -> 0 | AP36: 0 | AQ36: =SUM(F36:J36)-SUM(AK36:AP36) -> 32000 | AR36: =IF( AX36<15001,0,IF(AX36<20001,150,200)) -> 200 | AS36: 0 | AT36: =MIN( ROUND(AB36*12%,0),1800) -> 1800 | AU36: =ROUNDUP(IF(E36<=21000,AG36*1.75%,0),0) -> 0 | AV36: =AU36 -> 0 | AW36: =SUM(V36:Z36)+SUM(AH36:AI36) -> 32000 | AX36: =AW36-AP36-SUM(AK36:AM36) -> 32000 | AY36: =SUM(AK36:AP36)+SUM(AR36:AT36)+AV36 -> 2000 | AZ36: =AW36-AY36-BB36 -> 30000
A37: =A36+1 -> 34 | B37: B1 | C37: 40183 | E37: 120000 | F37: =E37*50% -> 60000 | G37: =F37*40% -> 24000 | H37: =IF(E37<11750,0,3500) -> 3500 | I37: 2400 | J37: =E37-SUM(F37:I37) -> 30100 | K37: 44774 | L37: =VLOOKUP(K37,SalaryMonth!$B$5:$E$16,2,FALSE) -> 44768 | M37: =VLOOKUP(K37,SalaryMonth!$B$5:$E$16,3,FALSE) -> 44798 | N37: =VLOOKUP(K37,SalaryMonth!$B$5:$E$16,4,FALSE) -> 31 | O37: =IF(L37<C37,"Y","N") -> N | P37: =IF(OR(D37<>"",M37<D37),"Y","N") -> N | Q37: 31 | R37: 31 | S37: 0 | T37: 0 | U37: 0 | V37: =ROUND((F37/N37)*Q37,0) -> 60000 | W37: =ROUND((G37/N37)*Q37,0) -> 24000 | X37: =ROUND((H37/N37)*Q37,0) -> 3500 | Y37: =(I37/N37)*Q37 -> 2400 | Z37: =ROUND((J37/N37)*Q37,0) -> 30100 | AB37: =ROUND((V37/Q37)*Q37-(V37/Q37)*S37,0) -> 60000 | AC37: =ROUND((W37/Q37)*Q37-(W37/Q37)*S37,0) -> 24000 | AD37: =ROUND((X37/Q37)*Q37-(X37/Q37)*S37,0) -> 3500 | AE37: =I37 -> 2400 | AF37: =ROUND((Z37/Q37)*Q37-(Z37/Q37)*S37,0) -> 30100 | AG37: =SUM(AB37:AF37) -> 120000 | AH37: 0 | AI37: 0 | AJ37: =SUM(AB37:AI37) -> 240000 | AK37: =SUM(V37:Z37)-AG37 -> 0 | AL37: =ROUND(E37*(U37/Q37),0) -> 0 | AM37: =ROUND(E37*(T37/Q37),0) -> 0 | AN37: 0 | AO37: =AE37 -> 2400 | AP37: 0 | AQ37: =SUM(F37:J37)-SUM(AK37:AP37) -> 117600 | AR37: =IF( AX37<15001,0,IF(AX37<20001,150,200)) -> 200 | AS37: 0 | AT37: =MIN( ROUND(AB37*12%,0),1800) -> 1800 | AU37: =ROUNDUP(IF(E37<=21000,AG37*1.75%,0),0) -> 0 | AV37: =AU37 -> 0 | AW37: =SUM(V37:Z37)+SUM(AH37:AI37) -> 120000 | AX37: =AW37-AP37-SUM(AK37:AM37) -> 120000 | AY37: =SUM(AK37:AP37)+SUM(AR37:AT37)+AV37 -> 4400 | AZ37: =AW37-AY37-BB37 -> 105290 | BA37: Income tax Added | BB37: 10310
A38: =A37+1 -> 35 | AK38: =SUM(V38:Z38)-AG38 -> 0 | AZ38: =AW38-AY38-BB38 -> 0
A39: =A38+1 -> 36 | B39: A1 | C39: 40180 | E39: 62000 | F39: =E39*50% -> 31000 | G39: =F39*40% -> 12400 | H39: =IF(E39<11750,0,3500) -> 3500 | I39: 0 | J39: =E39-SUM(F39:I39) -> 15100 | K39: 44805 | L39: =VLOOKUP(K39,SalaryMonth!$B$5:$E$16,2,FALSE) -> 44799 | M39: =VLOOKUP(K39,SalaryMonth!$B$5:$E$16,3,FALSE) -> 44829 | N39: =VLOOKUP(K39,SalaryMonth!$B$5:$E$16,4,FALSE) -> 31 | O39: =IF(L39<=C39,"Y","N") -> N | P39: =IF(OR(D39<>"",M39<D39),"Y","N") -> N | Q39: 31 | R39: 29 | S39: 1 | T39: 0 | U39: 0 | V39: =ROUND((F39/N39)*Q39,0) -> 31000 | W39: =ROUND((G39/N39)*Q39,0) -> 12400 | X39: =ROUND((H39/N39)*Q39,0) -> 3500 | Y39: =(I39/N39)*Q39 -> 0 | Z39: =ROUND((J39/N39)*Q39,0) -> 15100 | AB39: =ROUND((V39/Q39)*Q39-(V39/Q39)*S39,0) -> 30000 | AC39: =ROUND((W39/Q39)*Q39-(W39/Q39)*S39,0) -> 12000 | AD39: =ROUND((X39/Q39)*Q39-(X39/Q39)*S39,0) -> 3387 | AE39: =Y39 -> 0 | AF39: =ROUND((Z39/Q39)*Q39-(Z39/Q39)*S39,0) -> 14613 | AG39: =SUM(AB39:AF39) -> 60000 | AH39: 0 | AI39: 0 | AJ39: =SUM(AB39:AI39) -> 120000 | AK39: =SUM(V39:Z39)-AG39 -> 2000 | AL39: =ROUND(E39*(U39/Q39),0) -> 0 | AM39: =ROUND(E39*(T39/Q39),0) -> 0 | AN39: 8333 | AO39: =AE39 -> 0 | AP39: 2000 | AQ39: =SUM(F39:J39)-SUM(AK39:AP39) -> 49667 | AR39: =IF( AX39<15001,0,IF(AX39<20001,150,200)) -> 200 | AS39: 0 | AT39: =MIN( ROUND(AB39*12%,0),1800) -> 1800 | AU39: =ROUNDUP(IF(E39<=21000,AG39*1.75%,0),0) -> 0 | AV39: =AU39 -> 0 | AW39: =SUM(V39:Z39)+SUM(AH39:AI39) -> 62000 | AX39: =AW39-AP39-SUM(AK39:AM39) -> 58000 | AY39: =SUM(AK39:AP39)+SUM(AR39:AT39)+AV39 -> 14333 | AZ39: =AW39-AY39-BB39 -> 43597 | BA39: Paycut added 2000/Advance Deducted 8333 | BB39: 4070
A40: =A39+1 -> 37 | B40: A2 | C40: 40180 | E40: 24000 | F40: =E40*50% -> 12000 | G40: =F40*40% -> 4800 | H40: =IF(E40<11750,0,3500) -> 3500 | I40: 0 | J40: =E40-SUM(F40:I40) -> 3700 | K40: 44805 | L40: =VLOOKUP(K40,SalaryMonth!$B$5:$E$16,2,FALSE) -> 44799 | M40: =VLOOKUP(K40,SalaryMonth!$B$5:$E$16,3,FALSE) -> 44829 | N40: =VLOOKUP(K40,SalaryMonth!$B$5:$E$16,4,FALSE) -> 31 | O40: =IF(L40<C40,"Y","N") -> N | P40: =IF(OR(D40<>"",M40<D40),"Y","N") -> N | Q40: 31 | R40: 29 | S40: 0 | T40: 0 | U40: 0 | V40: =ROUND((F40/N40)*Q40,0) -> 12000 | W40: =ROUND((G40/N40)*Q40,0) -> 4800 | X40: =ROUND((H40/N40)*Q40,0) -> 3500 | Y40: =(I40/N40)*Q40 -> 0 | Z40: =ROUND((J40/N40)*Q40,0) -> 3700 | AB40: =ROUND((V40/Q40)*Q40-(V40/Q40)*S40,0) -> 12000 | AC40: =ROUND((W40/Q40)*Q40-(W40/Q40)*S40,0) -> 4800 | AD40: =ROUND((X40/Q40)*Q40-(X40/Q40)*S40,0) -> 3500 | AE40: =Y40 -> 0 | AF40: =ROUND((Z40/Q40)*Q40-(Z40/Q40)*S40,0) -> 3700 | AG40: =SUM(AB40:AF40) -> 24000 | AH40: 0 | AI40: 0 | AJ40: =SUM(AB40:AI40) -> 48000 | AK40: =SUM(V40:Z40)-AG40 -> 0 | AL40: =ROUND(E40*(U40/Q40),0) -> 0 | AM40: =ROUND(E40*(T40/Q40),0) -> 0 | AN40: 0 | AO40: =AE40 -> 0 | AP40: 0 | AQ40: =SUM(F40:J40)-SUM(AK40:AP40) -> 24000 | AR40: =IF( AX40<15001,0,IF(AX40<20001,150,200)) -> 200 | AS40: 0 | AT40: =MIN( ROUND(AB40*12%,0),1800) -> 1440 | AU40: =ROUNDUP(IF(E40<=21000,AG40*1.75%,0),0) -> 0 | AV40: =ROUNDUP(AG40 *1.75%,0) -> 420 | AW40: =SUM(V40:Z40)+SUM(AH40:AI40) -> 24000 | AX40: =AW40-AP40-SUM(AK40:AM40) -> 24000 | AY40: =SUM(AK40:AP40)+SUM(AR40:AT40)+AV40 -> 2060 | AZ40: =AW40-AY40-BB40 -> 21940 | BA40: ESI should be deducted because ESI is deducted in May month it will continue up to sep irrespective of salary
...

Sheet SalaryValues
A1: S.No | B1: Employee Code | C1: DOJ | D1: DOR | E1: Salary | F1: Basic | G1: HRA | H1: Medical & Transport Allowance | I1: Food Coupons | J1: Special Allowance | K1: Month | L1: Month Start | M1: Month End | N1: Month Days | O1: Is New Employee | P1: Is Left Employee | Q1: Employee Working days | R1: Days present | S1: LOP Days | T1: Late Coming days | U1: Unauthorized leaves | V1: Basic | W1: HRA | X1: Medical & Transport Allowance | Y1: Food Coupons | Z1: Special Allowance | AB1: Basic | AC1: HRA | AD1: Medical & Transport Allowance | AE1: Food Coupons | AF1: Special Allowance | AG1: Salary Earned (For ESI) | AH1: Arrears | AI1: Incentives | AJ1: Gross Earnings Total | AK1: LOP Amount | AL1: UA Amount | AM1: LC Amount | AN1: Staff Salary Advances | AO1: Food Coupons | AP1: Paycut | AQ1: Net Salary Earned | AR1: PT | AS1: Income Tax | AT1: PF Employee Contribution | AU1: ESI Employee Contribution | AV1: ESI Final | AW1: Gross Earnings | AX1: Gross Earnings For Tax | AY1: Gross Deduction | AZ1: Net Take Home | BA1: Comments
A2: 1 | B2: A1 | C2: 40180 | E2: 62000 | F2: 31000 | G2: 12400 | H2: 3500 | I2: 0 | J2: 15100 | K2: 44652 | L2: 44646 | M2: 44676 | N2: 31 | O2: N | P2: N | Q2: 31 | R2: 28 | S2: 1 | T2: 1 | U2: 1 | V2: 31000 | W2: 12400 | X2: 3500 | Y2: 0 | Z2: 15100 | AB2: 30000 | AC2: 12000 | AD2: 3387 | AE2: 0 | AF2: 14613 | AG2: 60000 | AH2: 1000 | AI2: 1000 | AJ2: 122000 | AK2: 2000 | AL2: 2000 | AM2: 2000 | AN2: 8333 | AO2: 0 | AP2: 200 | AQ2: 47467 | AR2: 200 | AS2: 500 | AT2: 1800 | AU2: 0 | AV2: 0 | AW2: 64000 | AX2: 57800 | AY2: 17033 | AZ2: 46967 | BA2: Arrears Incentives Added /Advance Deducted 8333/LATE Coming /UnAuthorized/incometax
A3: 2 | B3: A2 | C3: 40180 | E3: 22000 | F3: 11000 | G3: 4400 | H3: 3500 | I3: 0 | J3: 3100 | K3: 44652 | L3: 44646 | M3: 44676 | N3: 31 | O3: N | P3: N | Q3: 31 | R3: 29 | S3: 0 | T3: 0 | U3: 0 | V3: 11000 | W3: 4400 | X3: 3500 | Y3: 0 | Z3: 3100 | AB3: 11000 | AC3: 4400 | AD3: 3500 | AE3: 0 | AF3: 3100 | AG3: 22000 | AH3: 0 | AI3: 0 | AJ3: 44000 | AK3: 0 | AL3: 0 | AM3: 0 | AN3: 0 | AO3: 0 | AP3: 0 | AQ3: 22000 | AR3: 200 | AS3: 0 | AT3: 1320 | AU3: 0 | AV3: 0 | AW3: 22000 | AX3: 22000 | AY3: 1520 | AZ3: 20480 | BA3: ESI is not deducted because Employee salary is Not under ESI slab
A4: 3 | B4: A3 | C4: 40181 | E4: 11000 | F4: 5500 | G4: 2200 | H4: 0 | I4: 0 | J4: 3300 | K4: 44652 | L4: 44646 | M4: 44676 | N4: 31 | O4: N | P4: N | Q4: 31 | R4: 29 | S4: 0 | T4: 0 | U4: 0 | V4: 5500 | W4: 2200 | X4: 0 | Y4: 0 | Z4: 3300 | AB4: 5500 | AC4: 2200 | AD4: 0 | AE4: 0 | AF4: 3300 | AG4: 11000 | AH4: 0 | AI4: 0 | AJ4: 22000 | AK4: 0 | AL4: 0 | AM4: 0 | AN4: 0 | AO4: 0 | AP4: 0 | AQ4: 11000 | AR4: 0 | AS4: 0 | AT4: 660 | AU4: 193 | AV4: 193 | AW4: 11000 | AX4: 11000 | AY4: 853 | AZ4: 10147 | BA4: ESI is deducted because employee salary is under ESI slab
A5: 4 | B5: A4 | C5: 40182 | E5: 25000 | F5: 12500 | G5: 5000 | H5: 3500 | I5: 0 | J5: 4000 | K5: 44652 | L5: 44646 | M5: 44676 | N5: 31 | O5: N | P5: N | Q5: 31 | R5: 29 | S5: 0 | T5: 0 | U5: 0 | V5: 12500 | W5: 5000 | X5: 3500 | Y5: 0 | Z5: 4000 | AB5: 12500 | AC5: 5000 | AD5: 3500 | AE5: 0 | AF5: 4000 | AG5: 25000 | AH5: 0 | AI5: 0 | AJ5: 50000 | AK5: 0 | AL5: 0 | AM5: 0 | AN5: 0 | AO5: 0 | AP5: 0 | AQ5: 25000 | AR5: 200 | AS5: 0 | AT5: 1500 | AU5: 0 | AV5: 0 | AW5: 25000 | AX5: 25000 | AY5: 1700 | AZ5: 23300
A6: 5 | B6: A5 | C6: 40183 | E6: 45000 | F6: 22500 | G6: 9000 | H6: 3500 | I6: 2400 | J6: 7600 | K6: 44652 | L6: 44646 | M6: 44676 | N6: 31 | O6: N | P6: N | Q6: 31 | R6: 29 | S6: 0 | T6: 0 | U6: 0 | V6: 22500 | W6: 9000 | X6: 3500 | Y6: 2400 | Z6: 7600 | AB6: 22500 | AC6: 9000 | AD6: 3500 | AE6: 2400 | AF6: 7600 | AG6: 45000 | AH6: 0 | AI6: 0 | AJ6: 90000 | AK6: 0 | AL6: 0 | AM6: 0 | AN6: 0 | AO6: 2400 | AP6: 0 | AQ6: 42600 | AR6: 200 | AS6: 2000 | AT6: 1800 | AU6: 0 | AV6: 0 | AW6: 45000 | AX6: 45000 | AY6: 6400 | AZ6: 38600 | BA6: Income tax Added
A7: 6 | AK7: 0
A8: 7 | B8: A1 | C8: 40180 | E8: 62000 | F8: 31000 | G8: 12400 | H8: 3500 | I8: 0 | J8: 15100 | K8: 44682 | L8: 44677 | M8: 44706 | N8: 30 | O8: N | P8: N | Q8: 30 | R8: 29 | S8: 1 | T8: 0 | U8: 0 | V8: 31000 | W8: 12400 | X8: 3500 | Y8: 0 | Z8: 15100 | AB8: 29967 | AC8: 11987 | AD8: 3383 | AE8: 0 | AF8: 14597 | AG8: 59934 | AH8: 0 | AI8: 1000 | AJ8: 120868 | AK8: 2066 | AL8: 0 | AM8: 0 | AN8: 8333 | AO8: 0 | AP8: 0 | AQ8: 51601 | AR8: 200 | AS8: 0 | AT8: 1800 | AU8: 0 | AV8: 0 | AW8: 63000 | AX8: 60934 | AY8: 12399 | AZ8: 50601 | BA8: incentives Added 1000rs/Advance Deducted 8333
A9: 8 | B9: A2 | C9: 40180 | E9: 21000 | F9: 10500 | G9: 4200 | H9: 3500 | I9: 0 | J9: 2800 | K9: 44682 | L9: 44677 | M9: 44706 | N9: 30 | O9: N | P9: N | Q9: 30 | R9: 29 | S9: 0 | T9: 0 | U9: 0 | V9: 10500 | W9: 4200 | X9: 3500 | Y9: 0 | Z9: 2800 | AB9: 10500 | AC9: 4200 | AD9: 3500 | AE9: 0 | AF9: 2800 | AG9: 21000 | AH9: 0 | AI9: 0 | AJ9: 42000 | AK9: 0 | AL9: 0 | AM9: 0 | AN9: 0 | AO9: 0 | AP9: 0 | AQ9: 21000 | AR9: 200 | AS9: 0 | AT9: 1260 | AU9: 368 | AV9: 368 | AW9: 21000 | AX9: 21000 | AY9: 1828 | AZ9: 19172 | BA9: ESI is deducted because employee salary is under ESI slab
A10: 9 | B10: A3 | C10: 40181 | E10: 11000 | F10: 5500 | G10: 2200 | H10: 0 | I10: 0 | J10: 3300 | K10: 44682 | L10: 44677 | M10: 44706 | N10: 30 | O10: N | P10: N | Q10: 30 | R10: 29 | S10: 0 | T10: 0 | U10: 0 | V10: 5500 | W10: 2200 | X10: 0 | Y10: 0 | Z10: 3300 | AB10: 5500 | AC10: 2200 | AD10: 0 | AE10: 0 | AF10: 3300 | AG10: 11000 | AH10: 0 | AI10: 0 | AJ10: 22000 | AK10: 0 | AL10: 0 | AM10: 0 | AN10: 0 | AO10: 0 | AP10: 0 | AQ10: 11000 | AR10: 0 | AS10: 0 | AT10: 660 | AU10: 193 | AV10: 193 | AW10: 11000 | AX10: 11000 | AY10: 853 | AZ10: 10147 | BA10: ESI is deducted because employee salary is under ESI slab
